Workbook

Sheet Guide
A1: SDAIA Academy — Success Story Publication Prioritization Framework
A2: Scores and ranks all 168 validated success stories to decide which are published first · data as of 7 Oct 2026 (SuccessStories/website/js/data.js)
A5: How to use
A6: 1 | B6: Adjust the criterion weights on the Weights sheet (yellow cells). Scores, ranks, tiers and the Top 30 update automatically.
A7: 2 | B7: Override any criterion score (0–5) on the Scoring sheet if you disagree with the assessment. Blue values are editable inputs.
A8: 3 | B8: Use the Editorial Adj. column (−10 to +10 points) to lift or lower a story for slate balance, e.g. to cap stories from one employer.
A9: 4 | B9: Set Hold Flag to "Yes" to remove a story from the ranking until its issue is resolved; it moves to "Hold – resolve flag".
A10: 5 | B10: Read the Top 30 sheet for the publication queue and the Pre-publication Actions column for what each story needs before going live.
A11: 6 | B11: Set Added to Queue to "Yes" on the Scoring sheet to put a story in the Priority Queue regardless of its rank; it is tiered at least Tier 2 – Priority.
A13: Colour legend
A14: Blue text, yellow fill | B14: Editable input (weights, criterion scores, adjustments, hold flags, tier cut-offs)
A15: Black text | B15: Formula — do not overwrite
A16: Green text | B16: Link pulled from another sheet
A18: Publishing tiers
A19: Tier 1 – Flagship launch | B19: Ranks 1–10. Lead the launch; homepage, press and executive reporting.
A20: Tier 2 – Priority | B20: Ranks 11–30, plus any story added to the queue by hand (Added to Queue = Yes). Publish in the following fortnightly batches; social media features.
A21: Tier 3 – Standard rotation | B21: Ranks 31–80. Rolling publication on the Success Stories page.
A22: Tier 4 – Reserve | B22: Rank 81 and below. Published in the catalogue; not featured.
A23: Hold – resolve flag | B23: Legacy gap-flagged stories (authorized exception) and stories with an undisclosed employer. Not featured until resolved.
A25: Method notes
A26: Score | B26: Priority Score = Σ(criterion score × weight) ÷ Σ weights ÷ 5 × 100, plus editorial adjustment, bounded 0–100.
A27: Rank | B27: Eligible stories rank first, by score; ties break by sheet order. Held stories rank after all eligible ones.
A28: Time since training | B28: Interpreted as the months from programme completion to the outcome (shorter scores higher). Cohort recency is scored under Strategic relevance.
A29: Initial scores | B29: Criterion scores were assessed from each story record (role, employer, dates, links, achievements, photo, quote status) using the rubrics on the Weights sheet.
A30: Rationale | B30: The Rationale text is written from the default weights; it does not rewrite itself when weights change.
A31: Added names (7 Oct) | B31: 38 names were added to the queue; all 38 already existed among the 168 stories (no new or duplicate records), and 8 were already in the Top 30. They are flagged Added to Queue = Yes rather than duplicated.
A32: Eligibility basis | B32: SDAIA Success Story Policy v1.0 (14-month criterion). All 168 stories are already validated; this framework only orders them.

Sheet Priority Queue
A1: Priority Queue — Top 30 by score + stories added to the queue
A2: Live from the Scoring sheet, ordered by priority score. Held stories sit at the end. Set "Added to Queue" on the Scoring sheet to add or remove a story.
A3: Stories in queue: | C3: =SUMPRODUCT(--((Scoring!$Z$5:$Z$172<=Weights!$C$19)+(Scoring!$AF$5:$AF$172="Yes")>0)) -> 60
A4: Queue # | B4: Overall Rank | C4: Source | D4: Story ID | E4: Name (AR) | F4: Name (EN) | G4: Employer | H4: Track | I4: Cohort | J4: Months to Outcome | K4: Priority Score | L4: Publishing Tier | M4: Rationale | N4: Pre-publication Actions | O4: Quote Status
A5: =IF(1<=$C$3,1,"") -> 1 | B5: =IF($A5="","",INDEX(Scoring!$Z$5:$Z$172,MATCH(1,Scoring!$AH$5:$AH$172,0))) -> 1 | C5: =IF($A5="","",IF(INDEX(Scoring!$AF$5:$AF$172,MATCH(1,Scoring!$AH$5:$AH$172,0))="Yes",IF(INDEX(Scoring!$Z$5:$Z$172,MATCH(1,Scoring!$AH$5:$AH$172,0))<=Weights!$C$19,"Top 30 + added","Added to queue"),"Top 30 by score")) -> Top 30 by score | D5: =IF($A5="","",INDEX(Scoring!$A$5:$A$172,MATCH(1,Scoring!$AH$5:$AH$172,0))) -> aqeelah-makki | E5: =IF($A5="","",INDEX(Scoring!$B$5:$B$172,MATCH(1,Scoring!$AH$5:$AH$172,0))) -> عقيلة مكي | F5: =IF($A5="","",INDEX(Scoring!$C$5:$C$172,MATCH(1,Scoring!$AH$5:$AH$172,0))) -> Aqeelah Jaffar Makki | G5: =IF($A5="","",INDEX(Scoring!$D$5:$D$172,MATCH(1,Scoring!$AH$5:$AH$172,0))) -> هيوماين (HUMAIN) | H5: =IF($A5="","",INDEX(Scoring!$F$5:$F$172,MATCH(1,Scoring!$AH$5:$AH$172,0))) -> GenAI / NVIDIA | I5: =IF($A5="","",INDEX(Scoring!$G$5:$G$172,MATCH(1,Scoring!$AH$5:$AH$172,0))) -> 2023 | J5: =IF($A5="","",INDEX(Scoring!$H$5:$H$172,MATCH(1,Scoring!$AH$5:$AH$172,0))) -> 1 | K5: =IF($A5="","",INDEX(Scoring!$W$5:$W$172,MATCH(1,Scoring!$AH$5:$AH$172,0))) -> 86.1 | L5: =IF($A5="","",INDEX(Scoring!$AA$5:$AA$172,MATCH(1,Scoring!$AH$5:$AH$172,0))) -> Tier 1 – Flagship launch | M5: =IF($A5="","",INDEX(Scoring!$AB$5:$AB$172,MATCH(1,Scoring!$AH$5:$AH$172,0))) -> Strengths: Employer / company profile 5/5, Employment after training 5/5, Measurable impact 5/5. GenAI / NVIDIA track, cohort 2023; 1 month to outcome. Weak on: Promotion. | N5: =IF($A5="","",INDEX(Scoring!$AD$5:$AD$172,MATCH(1,Scoring!$AH$5:$AH$172,0))) -> Clear draft quote with graduate | O5: =IF($A5="","",INDEX(Scoring!$AE$5:$AE$172,MATCH(1,Scoring!$AH$5:$AH$172,0))) -> Draft
A6: =IF(2<=$C$3,2,"") -> 2 | B6: =IF($A6="","",INDEX(Scoring!$Z$5:$Z$172,MATCH(2,Scoring!$AH$5:$AH$172,0))) -> 2 | C6: =IF($A6="","",IF(INDEX(Scoring!$AF$5:$AF$172,MATCH(2,Scoring!$AH$5:$AH$172,0))="Yes",IF(INDEX(Scoring!$Z$5:$Z$172,MATCH(2,Scoring!$AH$5:$AH$172,0))<=Weights!$C$19,"Top 30 + added","Added to queue"),"Top 30 by score")) -> Top 30 by score | D6: =IF($A6="","",INDEX(Scoring!$A$5:$A$172,MATCH(2,Scoring!$AH$5:$AH$172,0))) -> khaled-almutairy | E6: =IF($A6="","",INDEX(Scoring!$B$5:$B$172,MATCH(2,Scoring!$AH$5:$AH$172,0))) -> خالد المطيري | F6: =IF($A6="","",INDEX(Scoring!$C$5:$C$172,MATCH(2,Scoring!$AH$5:$AH$172,0))) -> Khaled Almutairy | G6: =IF($A6="","",INDEX(Scoring!$D$5:$D$172,MATCH(2,Scoring!$AH$5:$AH$172,0))) -> شركة علم | H6: =IF($A6="","",INDEX(Scoring!$F$5:$F$172,MATCH(2,Scoring!$AH$5:$AH$172,0))) -> GenAI / NVIDIA | I6: =IF($A6="","",INDEX(Scoring!$G$5:$G$172,MATCH(2,Scoring!$AH$5:$AH$172,0))) -> 2025 | J6: =IF($A6="","",INDEX(Scoring!$H$5:$H$172,MATCH(2,Scoring!$AH$5:$AH$172,0))) -> 1 | K6: =IF($A6="","",INDEX(Scoring!$W$5:$W$172,MATCH(2,Scoring!$AH$5:$AH$172,0))) -> 78.7 | L6: =IF($A6="","",INDEX(Scoring!$AA$5:$AA$172,MATCH(2,Scoring!$AH$5:$AH$172,0))) -> Tier 1 – Flagship launch | M6: =IF($A6="","",INDEX(Scoring!$AB$5:$AB$172,MATCH(2,Scoring!$AH$5:$AH$172,0))) -> Strengths: Employer / company profile 5/5, Employment after training 5/5, Specialization 5/5. GenAI / NVIDIA track, cohort 2025; 1 month to outcome. Weak on: Promotion. | N6: =IF($A6="","",INDEX(Scoring!$AD$5:$AD$172,MATCH(2,Scoring!$AH$5:$AH$172,0))) -> Clear draft quote with graduate | O6: =IF($A6="","",INDEX(Scoring!$AE$5:$AE$172,MATCH(2,Scoring!$AH$5:$AH$172,0))) -> Draft
A7: =IF(3<=$C$3,3,"") -> 3 | B7: =IF($A7="","",INDEX(Scoring!$Z$5:$Z$172,MATCH(3,Scoring!$AH$5:$AH$172,0))) -> 3 | C7: =IF($A7="","",IF(INDEX(Scoring!$AF$5:$AF$172,MATCH(3,Scoring!$AH$5:$AH$172,0))="Yes",IF(INDEX(Scoring!$Z$5:$Z$172,MATCH(3,Scoring!$AH$5:$AH$172,0))<=Weights!$C$19,"Top 30 + added","Added to queue"),"Top 30 by score")) -> Top 30 by score | D7: =IF($A7="","",INDEX(Scoring!$A$5:$A$172,MATCH(3,Scoring!$AH$5:$AH$172,0))) -> asma-alzubaidi | E7: =IF($A7="","",INDEX(Scoring!$B$5:$B$172,MATCH(3,Scoring!$AH$5:$AH$172,0))) -> اسماء احمد الزبيدي | F7: =IF($A7="","",INDEX(Scoring!$C$5:$C$172,MATCH(3,Scoring!$AH$5:$AH$172,0))) -> Asma Ahmed Alzubaidi | G7: =IF($A7="","",INDEX(Scoring!$D$5:$D$172,MATCH(3,Scoring!$AH$5:$AH$172,0))) -> جامعة أم القرى | H7: =IF($A7="","",INDEX(Scoring!$F$5:$F$172,MATCH(3,Scoring!$AH$5:$AH$172,0))) -> GenAI / NVIDIA | I7: =IF($A7="","",INDEX(Scoring!$G$5:$G$172,MATCH(3,Scoring!$AH$5:$AH$172,0))) -> 2025 | J7: =IF($A7="","",INDEX(Scoring!$H$5:$H$172,MATCH(3,Scoring!$AH$5:$AH$172,0))) -> 11 | K7: =IF($A7="","",INDEX(Scoring!$W$5:$W$172,MATCH(3,Scoring!$AH$5:$AH$172,0))) -> 75.7 | L7: =IF($A7="","",INDEX(Scoring!$AA$5:$AA$172,MATCH(3,Scoring!$AH$5:$AH$172,0))) -> Tier 1 – Flagship launch | M7: =IF($A7="","",INDEX(Scoring!$AB$5:$AB$172,MATCH(3,Scoring!$AH$5:$AH$172,0))) -> Strengths: Evidence quality 4.5/5, Employment after training 5/5, Employer / company profile 4/5. GenAI / NVIDIA track, cohort 2025; 11 months to outcome. Weak on: Time since training. | N7: =IF($A7="","",INDEX(Scoring!$AD$5:$AD$172,MATCH(3,Scoring!$AH$5:$AH$172,0))) -> Ready | O7: =IF($A7="","",INDEX(Scoring!$AE$5:$AE$172,MATCH(3,Scoring!$AH$5:$AH$172,0))) -> Verified
A8: =IF(4<=$C$3,4,"") -> 4 | B8: =IF($A8="","",INDEX(Scoring!$Z$5:$Z$172,MATCH(4,Scoring!$AH$5:$AH$172,0))) -> 4 | C8: =IF($A8="","",IF(INDEX(Scoring!$AF$5:$AF$172,MATCH(4,Scoring!$AH$5:$AH$172,0))="Yes",IF(INDEX(Scoring!$Z$5:$Z$172,MATCH(4,Scoring!$AH$5:$AH$172,0))<=Weights!$C$19,"Top 30 + added","Added to queue"),"Top 30 by score")) -> Top 30 by score | D8: =IF($A8="","",INDEX(Scoring!$A$5:$A$172,MATCH(4,Scoring!$AH$5:$AH$172,0))) -> farah-alsuwayeh | E8: =IF($A8="","",INDEX(Scoring!$B$5:$B$172,MATCH(4,Scoring!$AH$5:$AH$172,0))) -> فرح السويح | F8: =IF($A8="","",INDEX(Scoring!$C$5:$C$172,MATCH(4,Scoring!$AH$5:$AH$172,0))) -> Farah Alsuwayeh | G8: =IF($A8="","",INDEX(Scoring!$D$5:$D$172,MATCH(4,Scoring!$AH$5:$AH$172,0))) -> السعودية للطاقة | H8: =IF($A8="","",INDEX(Scoring!$F$5:$F$172,MATCH(4,Scoring!$AH$5:$AH$172,0))) -> LLM | I8: =IF($A8="","",INDEX(Scoring!$G$5:$G$172,MATCH(4,Scoring!$AH$5:$AH$172,0))) -> 2023 | J8: =IF($A8="","",INDEX(Scoring!$H$5:$H$172,MATCH(4,Scoring!$AH$5:$AH$172,0))) -> 1 | K8: =IF($A8="","",INDEX(Scoring!$W$5:$W$172,MATCH(4,Scoring!$AH$5:$AH$172,0))) -> 75.3 | L8: =IF($A8="","",INDEX(Scoring!$AA$5:$AA$172,MATCH(4,Scoring!$AH$5:$AH$172,0))) -> Tier 1 – Flagship launch | M8: =IF($A8="","",INDEX(Scoring!$AB$5:$AB$172,MATCH(4,Scoring!$AH$5:$AH$172,0))) -> Strengths: Employer / company profile 5/5, Employment after training 5/5, Specialization 5/5. LLM track, cohort 2023; 1 month to outcome. Weak on: Promotion. | N8: =IF($A8="","",INDEX(Scoring!$AD$5:$AD$172,MATCH(4,Scoring!$AH$5:$AH$172,0))) -> Clear draft quote with graduate | O8: =IF($A8="","",INDEX(Scoring!$AE$5:$AE$172,MATCH(4,Scoring!$AH$5:$AH$172,0))) -> Draft
A9: =IF(5<=$C$3,5,"") -> 5 | B9: =IF($A9="","",INDEX(Scoring!$Z$5:$Z$172,MATCH(5,Scoring!$AH$5:$AH$172,0))) -> 5 | C9: =IF($A9="","",IF(INDEX(Scoring!$AF$5:$AF$172,MATCH(5,Scoring!$AH$5:$AH$172,0))="Yes",IF(INDEX(Scoring!$Z$5:$Z$172,MATCH(5,Scoring!$AH$5:$AH$172,0))<=Weights!$C$19,"Top 30 + added","Added to queue"),"Top 30 by score")) -> Top 30 by score | D9: =IF($A9="","",INDEX(Scoring!$A$5:$A$172,MATCH(5,Scoring!$AH$5:$AH$172,0))) -> hoor-alshihi | E9: =IF($A9="","",INDEX(Scoring!$B$5:$B$172,MATCH(5,Scoring!$AH$5:$AH$172,0))) -> حور الشيحي | F9: =IF($A9="","",INDEX(Scoring!$C$5:$C$172,MATCH(5,Scoring!$AH$5:$AH$172,0))) -> Hoor Al-Shihi | G9: =IF($A9="","",INDEX(Scoring!$D$5:$D$172,MATCH(5,Scoring!$AH$5:$AH$172,0))) -> SITE سايت | H9: =IF($A9="","",INDEX(Scoring!$F$5:$F$172,MATCH(5,Scoring!$AH$5:$AH$172,0))) -> Machine Learning | I9: =IF($A9="","",INDEX(Scoring!$G$5:$G$172,MATCH(5,Scoring!$AH$5:$AH$172,0))) -> 2023 | J9: =IF($A9="","",INDEX(Scoring!$H$5:$H$172,MATCH(5,Scoring!$AH$5:$AH$172,0))) -> n/a | K9: =IF($A9="","",INDEX(Scoring!$W$5:$W$172,MATCH(5,Scoring!$AH$5:$AH$172,0))) -> 75 | L9: =IF($A9="","",INDEX(Scoring!$AA$5:$AA$172,MATCH(5,Scoring!$AH$5:$AH$172,0))) -> Tier 1 – Flagship launch | M9: =IF($A9="","",INDEX(Scoring!$AB$5:$AB$172,MATCH(5,Scoring!$AH$5:$AH$172,0))) -> Strengths: Employment after training 5/5, Measurable impact 5/5, Employer / company profile 4/5. Machine Learning track, cohort 2023; timing dated by year only. Weak on: Career transition. | N9: =IF($A9="","",INDEX(Scoring!$AD$5:$AD$172,MATCH(5,Scoring!$AH$5:$AH$172,0))) -> Clear draft quote with graduate | O9: =IF($A9="","",INDEX(Scoring!$AE$5:$AE$172,MATCH(5,Scoring!$AH$5:$AH$172,0))) -> Draft
A10: =IF(6<=$C$3,6,"") -> 6 | B10: =IF($A10="","",INDEX(Scoring!$Z$5:$Z$172,MATCH(6,Scoring!$AH$5:$AH$172,0))) -> 6 | C10: =IF($A10="","",IF(INDEX(Scoring!$AF$5:$AF$172,MATCH(6,Scoring!$AH$5:$AH$172,0))="Yes",IF(INDEX(Scoring!$Z$5:$Z$172,MATCH(6,Scoring!$AH$5:$AH$172,0))<=Weights!$C$19,"Top 30 + added","Added to queue"),"Top 30 by score")) -> Top 30 + added | D10: =IF($A10="","",INDEX(Scoring!$A$5:$A$172,MATCH(6,Scoring!$AH$5:$AH$172,0))) -> abdulrahman-alqannas | E10: =IF($A10="","",INDEX(Scoring!$B$5:$B$172,MATCH(6,Scoring!$AH$5:$AH$172,0))) -> عبدالرحمن القناص | F10: =IF($A10="","",INDEX(Scoring!$C$5:$C$172,MATCH(6,Scoring!$AH$5:$AH$172,0))) -> Abdulrahman Alqannas | G10: =IF($A10="","",INDEX(Scoring!$D$5:$D$172,MATCH(6,Scoring!$AH$5:$AH$172,0))) -> شركة علم | H10: =IF($A10="","",INDEX(Scoring!$F$5:$F$172,MATCH(6,Scoring!$AH$5:$AH$172,0))) -> LLM | I10: =IF($A10="","",INDEX(Scoring!$G$5:$G$172,MATCH(6,Scoring!$AH$5:$AH$172,0))) -> 2023 | J10: =IF($A10="","",INDEX(Scoring!$H$5:$H$172,MATCH(6,Scoring!$AH$5:$AH$172,0))) -> 11 | K10: =IF($A10="","",INDEX(Scoring!$W$5:$W$172,MATCH(6,Scoring!$AH$5:$AH$172,0))) -> 74 | L10: =IF($A10="","",INDEX(Scoring!$AA$5:$AA$172,MATCH(6,Scoring!$AH$5:$AH$172,0))) -> Tier 1 – Flagship launch | M10: =IF($A10="","",INDEX(Scoring!$AB$5:$AB$172,MATCH(6,Scoring!$AH$5:$AH$172,0))) -> Strengths: Evidence quality 4.2/5, Employer / company profile 5/5, Employment after training 5/5. LLM track, cohort 2023; 11 months to outcome. Weak on: Time since training, Career transition. | N10: =IF($A10="","",INDEX(Scoring!$AD$5:$AD$172,MATCH(6,Scoring!$AH$5:$AH$172,0))) -> Ready | O10: =IF($A10="","",INDEX(Scoring!$AE$5:$AE$172,MATCH(6,Scoring!$AH$5:$AH$172,0))) -> Verified
A11: =IF(7<=$C$3,7,"") -> 7 | B11: =IF($A11="","",INDEX(Scoring!$Z$5:$Z$172,MATCH(7,Scoring!$AH$5:$AH$172,0))) -> 7 | C11: =IF($A11="","",IF(INDEX(Scoring!$AF$5:$AF$172,MATCH(7,Scoring!$AH$5:$AH$172,0))="Yes",IF(INDEX(Scoring!$Z$5:$Z$172,MATCH(7,Scoring!$AH$5:$AH$172,0))<=Weights!$C$19,"Top 30 + added","Added to queue"),"Top 30 by score")) -> Top 30 by score | D11: =IF($A11="","",INDEX(Scoring!$A$5:$A$172,MATCH(7,Scoring!$AH$5:$AH$172,0))) -> raghad-alqobali | E11: =IF($A11="","",INDEX(Scoring!$B$5:$B$172,MATCH(7,Scoring!$AH$5:$AH$172,0))) -> رغد القبالي | F11: =IF($A11="","",INDEX(Scoring!$C$5:$C$172,MATCH(7,Scoring!$AH$5:$AH$172,0))) -> Raghad Alqobali | G11: =IF($A11="","",INDEX(Scoring!$D$5:$D$172,MATCH(7,Scoring!$AH$5:$AH$172,0))) -> سدايا | H11: =IF($A11="","",INDEX(Scoring!$F$5:$F$172,MATCH(7,Scoring!$AH$5:$AH$172,0))) -> LLM | I11: =IF($A11="","",INDEX(Scoring!$G$5:$G$172,MATCH(7,Scoring!$AH$5:$AH$172,0))) -> 2023 | J11: =IF($A11="","",INDEX(Scoring!$H$5:$H$172,MATCH(7,Scoring!$AH$5:$AH$172,0))) -> n/a | K11: =IF($A11="","",INDEX(Scoring!$W$5:$W$172,MATCH(7,Scoring!$AH$5:$AH$172,0))) -> 73.2 | L11: =IF($A11="","",INDEX(Scoring!$AA$5:$AA$172,MATCH(7,Scoring!$AH$5:$AH$172,0))) -> Tier 1 – Flagship launch | M11: =IF($A11="","",INDEX(Scoring!$AB$5:$AB$172,MATCH(7,Scoring!$AH$5:$AH$172,0))) -> Strengths: Evidence quality 4.8/5, Measurable impact 5/5, Specialization 5/5. LLM track, cohort 2023; timing dated by year only. Weak on: Promotion, Career transition. | N11: =IF($A11="","",INDEX(Scoring!$AD$5:$AD$172,MATCH(7,Scoring!$AH$5:$AH$172,0))) -> Clear draft quote with graduate; Replace GitHub avatar with real photo; Confirm month-level date | O11: =IF($A11="","",INDEX(Scoring!$AE$5:$AE$172,MATCH(7,Scoring!$AH$5:$AH$172,0))) -> Draft
A12: =IF(8<=$C$3,8,"") -> 8 | B12: =IF($A12="","",INDEX(Scoring!$Z$5:$Z$172,MATCH(8,Scoring!$AH$5:$AH$172,0))) -> 8 | C12: =IF($A12="","",IF(INDEX(Scoring!$AF$5:$AF$172,MATCH(8,Scoring!$AH$5:$AH$172,0))="Yes",IF(INDEX(Scoring!$Z$5:$Z$172,MATCH(8,Scoring!$AH$5:$AH$172,0))<=Weights!$C$19,"Top 30 + added","Added to queue"),"Top 30 by score")) -> Top 30 + added | D12: =IF($A12="","",INDEX(Scoring!$A$5:$A$172,MATCH(8,Scoring!$AH$5:$AH$172,0))) -> badr-alshamrani | E12: =IF($A12="","",INDEX(Scoring!$B$5:$B$172,MATCH(8,Scoring!$AH$5:$AH$172,0))) -> بدر علي الشمراني | F12: =IF($A12="","",INDEX(Scoring!$C$5:$C$172,MATCH(8,Scoring!$AH$5:$AH$172,0))) -> Badr Ali Alshamrani | G12: =IF($A12="","",INDEX(Scoring!$D$5:$D$172,MATCH(8,Scoring!$AH$5:$AH$172,0))) -> مستشفى الملك فيصل التخصصي ومركز الأبحاث | H12: =IF($A12="","",INDEX(Scoring!$F$5:$F$172,MATCH(8,Scoring!$AH$5:$AH$172,0))) -> AI Agents | I12: =IF($A12="","",INDEX(Scoring!$G$5:$G$172,MATCH(8,Scoring!$AH$5:$AH$172,0))) -> 2025 | J12: =IF($A12="","",INDEX(Scoring!$H$5:$H$172,MATCH(8,Scoring!$AH$5:$AH$172,0))) -> 3 | K12: =IF($A12="","",INDEX(Scoring!$W$5:$W$172,MATCH(8,Scoring!$AH$5:$AH$172,0))) -> 73.2 | L12: =IF($A12="","",INDEX(Scoring!$AA$5:$AA$172,MATCH(8,Scoring!$AH$5:$AH$172,0))) -> Tier 1 – Flagship launch | M12: =IF($A12="","",INDEX(Scoring!$AB$5:$AB$172,MATCH(8,Scoring!$AH$5:$AH$172,0))) -> Strengths: Employer / company profile 5/5, Evidence quality 4/5, Employment after training 5/5. AI Agents track, cohort 2025; 3 months to outcome. Weak on: Promotion, Career transition. | N12: =IF($A12="","",INDEX(Scoring!$AD$5:$AD$172,MATCH(8,Scoring!$AH$5:$AH$172,0))) -> Ready | O12: =IF($A12="","",INDEX(Scoring!$AE$5:$AE$172,MATCH(8,Scoring!$AH$5:$AH$172,0))) -> Verified
A13: =IF(9<=$C$3,9,"") -> 9 | B13: =IF($A13="","",INDEX(Scoring!$Z$5:$Z$172,MATCH(9,Scoring!$AH$5:$AH$172,0))) -> 9 | C13: =IF($A13="","",IF(INDEX(Scoring!$AF$5:$AF$172,MATCH(9,Scoring!$AH$5:$AH$172,0))="Yes",IF(INDEX(Scoring!$Z$5:$Z$172,MATCH(9,Scoring!$AH$5:$AH$172,0))<=Weights!$C$19,"Top 30 + added","Added to queue"),"Top 30 by score")) -> Top 30 + added | D13: =IF($A13="","",INDEX(Scoring!$A$5:$A$172,MATCH(9,Scoring!$AH$5:$AH$172,0))) -> anas-almana | E13: =IF($A13="","",INDEX(Scoring!$B$5:$B$172,MATCH(9,Scoring!$AH$5:$AH$172,0))) -> أنس المانع | F13: =IF($A13="","",INDEX(Scoring!$C$5:$C$172,MATCH(9,Scoring!$AH$5:$AH$172,0))) -> Anas Almana | G13: =IF($A13="","",INDEX(Scoring!$D$5:$D$172,MATCH(9,Scoring!$AH$5:$AH$172,0))) -> Quality Support Solutions | H13: =IF($A13="","",INDEX(Scoring!$F$5:$F$172,MATCH(9,Scoring!$AH$5:$AH$172,0))) -> Data Science & AI (T5) | I13: =IF($A13="","",INDEX(Scoring!$G$5:$G$172,MATCH(9,Scoring!$AH$5:$AH$172,0))) -> 2023 | J13: =IF($A13="","",INDEX(Scoring!$H$5:$H$172,MATCH(9,Scoring!$AH$5:$AH$172,0))) -> 1 | K13: =IF($A13="","",INDEX(Scoring!$W$5:$W$172,MATCH(9,Scoring!$AH$5:$AH$172,0))) -> 73.1 | L13: =IF($A13="","",INDEX(Scoring!$AA$5:$AA$172,MATCH(9,Scoring!$AH$5:$AH$172,0))) -> Tier 1 – Flagship launch | M13: =IF($A13="","",INDEX(Scoring!$AB$5:$AB$172,MATCH(9,Scoring!$AH$5:$AH$172,0))) -> Strengths: Employment after training 5/5, Specialization 5/5, Time since training 5/5. Data Science & AI (T5) track, cohort 2023; 1 month to outcome. | N13: =IF($A13="","",INDEX(Scoring!$AD$5:$AD$172,MATCH(9,Scoring!$AH$5:$AH$172,0))) -> Ready | O13: =IF($A13="","",INDEX(Scoring!$AE$5:$AE$172,MATCH(9,Scoring!$AH$5:$AH$172,0))) -> Verified
A14: =IF(10<=$C$3,10,"") -> 10 | B14: =IF($A14="","",INDEX(Scoring!$Z$5:$Z$172,MATCH(10,Scoring!$AH$5:$AH$172,0))) -> 10 | C14: =IF($A14="","",IF(INDEX(Scoring!$AF$5:$AF$172,MATCH(10,Scoring!$AH$5:$AH$172,0))="Yes",IF(INDEX(Scoring!$Z$5:$Z$172,MATCH(10,Scoring!$AH$5:$AH$172,0))<=Weights!$C$19,"Top 30 + added","Added to queue"),"Top 30 by score")) -> Top 30 by score | D14: =IF($A14="","",INDEX(Scoring!$A$5:$A$172,MATCH(10,Scoring!$AH$5:$AH$172,0))) -> shahad-altamimi | E14: =IF($A14="","",INDEX(Scoring!$B$5:$B$172,MATCH(10,Scoring!$AH$5:$AH$172,0))) -> شهد التميمي | F14: =IF($A14="","",INDEX(Scoring!$C$5:$C$172,MATCH(10,Scoring!$AH$5:$AH$172,0))) -> Shahad Altamimi | G14: =IF($A14="","",INDEX(Scoring!$D$5:$D$172,MATCH(10,Scoring!$AH$5:$AH$172,0))) -> أكاديمية الملك سلمان العالمية للغة العربية | H14: =IF($A14="","",INDEX(Scoring!$F$5:$F$172,MATCH(10,Scoring!$AH$5:$AH$172,0))) -> Applied AI (AAI) | I14: =IF($A14="","",INDEX(Scoring!$G$5:$G$172,MATCH(10,Scoring!$AH$5:$AH$172,0))) -> 2026 | J14: =IF($A14="","",INDEX(Scoring!$H$5:$H$172,MATCH(10,Scoring!$AH$5:$AH$172,0))) -> 2 | K14: =IF($A14="","",INDEX(Scoring!$W$5:$W$172,MATCH(10,Scoring!$AH$5:$AH$172,0))) -> 73.1 | L14: =IF($A14="","",INDEX(Scoring!$AA$5:$AA$172,MATCH(10,Scoring!$AH$5:$AH$172,0))) -> Tier 1 – Flagship launch | M14: =IF($A14="","",INDEX(Scoring!$AB$5:$AB$172,MATCH(10,Scoring!$AH$5:$AH$172,0))) -> Strengths: Evidence quality 4.5/5, Measurable impact 5/5, Employer / company profile 4/5. Applied AI (AAI) track, cohort 2026; 2 months to outcome. Weak on: Employment after training, Promotion. | N14: =IF($A14="","",INDEX(Scoring!$AD$5:$AD$172,MATCH(10,Scoring!$AH$5:$AH$172,0))) -> Clear draft quote with graduate | O14: =IF($A14="","",INDEX(Scoring!$AE$5:$AE$172,MATCH(10,Scoring!$AH$5:$AH$172,0))) -> Draft
A15: =IF(11<=$C$3,11,"") -> 11 | B15: =IF($A15="","",INDEX(Scoring!$Z$5:$Z$172,MATCH(11,Scoring!$AH$5:$AH$172,0))) -> 11 | C15: =IF($A15="","",IF(INDEX(Scoring!$AF$5:$AF$172,MATCH(11,Scoring!$AH$5:$AH$172,0))="Yes",IF(INDEX(Scoring!$Z$5:$Z$172,MATCH(11,Scoring!$AH$5:$AH$172,0))<=Weights!$C$19,"Top 30 + added","Added to queue"),"Top 30 by score")) -> Top 30 + added | D15: =IF($A15="","",INDEX(Scoring!$A$5:$A$172,MATCH(11,Scoring!$AH$5:$AH$172,0))) -> rayan-dahlawi | E15: =IF($A15="","",INDEX(Scoring!$B$5:$B$172,MATCH(11,Scoring!$AH$5:$AH$172,0))) -> ريان دحلوي | F15: =IF($A15="","",INDEX(Scoring!$C$5:$C$172,MATCH(11,Scoring!$AH$5:$AH$172,0))) -> Rayan Dahlawi | G15: =IF($A15="","",INDEX(Scoring!$D$5:$D$172,MATCH(11,Scoring!$AH$5:$AH$172,0))) -> عبداللطيف جميل المتحدة للتمويل | H15: =IF($A15="","",INDEX(Scoring!$F$5:$F$172,MATCH(11,Scoring!$AH$5:$AH$172,0))) -> LLM | I15: =IF($A15="","",INDEX(Scoring!$G$5:$G$172,MATCH(11,Scoring!$AH$5:$AH$172,0))) -> 2024 | J15: =IF($A15="","",INDEX(Scoring!$H$5:$H$172,MATCH(11,Scoring!$AH$5:$AH$172,0))) -> 5 | K15: =IF($A15="","",INDEX(Scoring!$W$5:$W$172,MATCH(11,Scoring!$AH$5:$AH$172,0))) -> 73.1 | L15: =IF($A15="","",INDEX(Scoring!$AA$5:$AA$172,MATCH(11,Scoring!$AH$5:$AH$172,0))) -> Tier 2 – Priority | M15: =IF($A15="","",INDEX(Scoring!$AB$5:$AB$172,MATCH(11,Scoring!$AH$5:$AH$172,0))) -> Strengths: Employment after training 5/5, Employer / company profile 4/5, Specialization 5/5. LLM track, cohort 2024; 5 months to outcome. Weak on: Promotion. | N15: =IF($A15="","",INDEX(Scoring!$AD$5:$AD$172,MATCH(11,Scoring!$AH$5:$AH$172,0))) -> Clear draft quote with graduate | O15: =IF($A15="","",INDEX(Scoring!$AE$5:$AE$172,MATCH(11,Scoring!$AH$5:$AH$172,0))) -> Draft
A16: =IF(12<=$C$3,12,"") -> 12 | B16: =IF($A16="","",INDEX(Scoring!$Z$5:$Z$172,MATCH(12,Scoring!$AH$5:$AH$172,0))) -> 12 | C16: =IF($A16="","",IF(INDEX(Scoring!$AF$5:$AF$172,MATCH(12,Scoring!$AH$5:$AH$172,0))="Yes",IF(INDEX(Scoring!$Z$5:$Z$172,MATCH(12,Scoring!$AH$5:$AH$172,0))<=Weights!$C$19,"Top 30 + added","Added to queue"),"Top 30 by score")) -> Top 30 + added | D16: =IF($A16="","",INDEX(Scoring!$A$5:$A$172,MATCH(12,Scoring!$AH$5:$AH$172,0))) -> abdulaziz-althumairy | E16: =IF($A16="","",INDEX(Scoring!$B$5:$B$172,MATCH(12,Scoring!$AH$5:$AH$172,0))) -> عبدالعزيز الثميري | F16: =IF($A16="","",INDEX(Scoring!$C$5:$C$172,MATCH(12,Scoring!$AH$5:$AH$172,0))) -> Abdulaziz Al-Thumairy | G16: =IF($A16="","",INDEX(Scoring!$D$5:$D$172,MATCH(12,Scoring!$AH$5:$AH$172,0))) -> صندوق الاستثمارات العامة (PIF) | H16: =IF($A16="","",INDEX(Scoring!$F$5:$F$172,MATCH(12,Scoring!$AH$5:$AH$172,0))) -> GenAI / NVIDIA | I16: =IF($A16="","",INDEX(Scoring!$G$5:$G$172,MATCH(12,Scoring!$AH$5:$AH$172,0))) -> 2024 | J16: =IF($A16="","",INDEX(Scoring!$H$5:$H$172,MATCH(12,Scoring!$AH$5:$AH$172,0))) -> 2 | K16: =IF($A16="","",INDEX(Scoring!$W$5:$W$172,MATCH(12,Scoring!$AH$5:$AH$172,0))) -> 72.9 | L16: =IF($A16="","",INDEX(Scoring!$AA$5:$AA$172,MATCH(12,Scoring!$AH$5:$AH$172,0))) -> Tier 2 – Priority | M16: =IF($A16="","",INDEX(Scoring!$AB$5:$AB$172,MATCH(12,Scoring!$AH$5:$AH$172,0))) -> Strengths: Employer / company profile 5/5, Employment after training 5/5, Time since training 5/5. GenAI / NVIDIA track, cohort 2024; 2 months to outcome. Weak on: Promotion. | N16: =IF($A16="","",INDEX(Scoring!$AD$5:$AD$172,MATCH(12,Scoring!$AH$5:$AH$172,0))) -> Clear draft quote with graduate | O16: =IF($A16="","",INDEX(Scoring!$AE$5:$AE$172,MATCH(12,Scoring!$AH$5:$AH$172,0))) -> Draft
A17: =IF(13<=$C$3,13,"") -> 13 | B17: =IF($A17="","",INDEX(Scoring!$Z$5:$Z$172,MATCH(13,Scoring!$AH$5:$AH$172,0))) -> 13 | C17: =IF($A17="","",IF(INDEX(Scoring!$AF$5:$AF$172,MATCH(13,Scoring!$AH$5:$AH$172,0))="Yes",IF(INDEX(Scoring!$Z$5:$Z$172,MATCH(13,Scoring!$AH$5:$AH$172,0))<=Weights!$C$19,"Top 30 + added","Added to queue"),"Top 30 by score")) -> Top 30 by score | D17: =IF($A17="","",INDEX(Scoring!$A$5:$A$172,MATCH(13,Scoring!$AH$5:$AH$172,0))) -> noura-alfouzan | E17: =IF($A17="","",INDEX(Scoring!$B$5:$B$172,MATCH(13,Scoring!$AH$5:$AH$172,0))) -> نورة الفوزان | F17: =IF($A17="","",INDEX(Scoring!$C$5:$C$172,MATCH(13,Scoring!$AH$5:$AH$172,0))) -> Noura Alfouzan | G17: =IF($A17="","",INDEX(Scoring!$D$5:$D$172,MATCH(13,Scoring!$AH$5:$AH$172,0))) -> المؤسسة العامة للمياه (Saudi Water Authority) | H17: =IF($A17="","",INDEX(Scoring!$F$5:$F$172,MATCH(13,Scoring!$AH$5:$AH$172,0))) -> Advanced AI Pathways | I17: =IF($A17="","",INDEX(Scoring!$G$5:$G$172,MATCH(13,Scoring!$AH$5:$AH$172,0))) -> 2024 | J17: =IF($A17="","",INDEX(Scoring!$H$5:$H$172,MATCH(13,Scoring!$AH$5:$AH$172,0))) -> n/a | K17: =IF($A17="","",INDEX(Scoring!$W$5:$W$172,MATCH(13,Scoring!$AH$5:$AH$172,0))) -> 72.3 | L17: =IF($A17="","",INDEX(Scoring!$AA$5:$AA$172,MATCH(13,Scoring!$AH$5:$AH$172,0))) -> Tier 2 – Priority | M17: =IF($A17="","",INDEX(Scoring!$AB$5:$AB$172,MATCH(13,Scoring!$AH$5:$AH$172,0))) -> Strengths: Employment after training 5/5, Measurable impact 4/5, Strategic relevance 5/5. Advanced AI Pathways track, cohort 2024; timing dated by year only. | N17: =IF($A17="","",INDEX(Scoring!$AD$5:$AD$172,MATCH(13,Scoring!$AH$5:$AH$172,0))) -> Clear draft quote with graduate | O17: =IF($A17="","",INDEX(Scoring!$AE$5:$AE$172,MATCH(13,Scoring!$AH$5:$AH$172,0))) -> Draft
A18: =IF(14<=$C$3,14,"") -> 14 | B18: =IF($A18="","",INDEX(Scoring!$Z$5:$Z$172,MATCH(14,Scoring!$AH$5:$AH$172,0))) -> 14 | C18: =IF($A18="","",IF(INDEX(Scoring!$AF$5:$AF$172,MATCH(14,Scoring!$AH$5:$AH$172,0))="Yes",IF(INDEX(Scoring!$Z$5:$Z$172,MATCH(14,Scoring!$AH$5:$AH$172,0))<=Weights!$C$19,"Top 30 + added","Added to queue"),"Top 30 by score")) -> Top 30 + added | D18: =IF($A18="","",INDEX(Scoring!$A$5:$A$172,MATCH(14,Scoring!$AH$5:$AH$172,0))) -> ahmed-almuaybid | E18: =IF($A18="","",INDEX(Scoring!$B$5:$B$172,MATCH(14,Scoring!$AH$5:$AH$172,0))) -> أحمد المعيبد | F18: =IF($A18="","",INDEX(Scoring!$C$5:$C$172,MATCH(14,Scoring!$AH$5:$AH$172,0))) -> Ahmed Almuaybid | G18: =IF($A18="","",INDEX(Scoring!$D$5:$D$172,MATCH(14,Scoring!$AH$5:$AH$172,0))) -> سابك | H18: =IF($A18="","",INDEX(Scoring!$F$5:$F$172,MATCH(14,Scoring!$AH$5:$AH$172,0))) -> Data Science & AI (T5) | I18: =IF($A18="","",INDEX(Scoring!$G$5:$G$172,MATCH(14,Scoring!$AH$5:$AH$172,0))) -> 2021 | J18: =IF($A18="","",INDEX(Scoring!$H$5:$H$172,MATCH(14,Scoring!$AH$5:$AH$172,0))) -> 4 | K18: =IF($A18="","",INDEX(Scoring!$W$5:$W$172,MATCH(14,Scoring!$AH$5:$AH$172,0))) -> 72 | L18: =IF($A18="","",INDEX(Scoring!$AA$5:$AA$172,MATCH(14,Scoring!$AH$5:$AH$172,0))) -> Tier 2 – Priority | M18: =IF($A18="","",INDEX(Scoring!$AB$5:$AB$172,MATCH(14,Scoring!$AH$5:$AH$172,0))) -> Strengths: Employer / company profile 5/5, Employment after training 5/5, Promotion 5/5. Data Science & AI (T5) track, cohort 2021; 4 months to outcome. Weak on: Career transition. | N18: =IF($A18="","",INDEX(Scoring!$AD$5:$AD$172,MATCH(14,Scoring!$AH$5:$AH$172,0))) -> Clear draft quote with graduate | O18: =IF($A18="","",INDEX(Scoring!$AE$5:$AE$172,MATCH(14,Scoring!$AH$5:$AH$172,0))) -> Draft
A19: =IF(15<=$C$3,15,"") -> 15 | B19: =IF($A19="","",INDEX(Scoring!$Z$5:$Z$172,MATCH(15,Scoring!$AH$5:$AH$172,0))) -> 15 | C19: =IF($A19="","",IF(INDEX(Scoring!$AF$5:$AF$172,MATCH(15,Scoring!$AH$5:$AH$172,0))="Yes",IF(INDEX(Scoring!$Z$5:$Z$172,MATCH(15,Scoring!$AH$5:$AH$172,0))<=Weights!$C$19,"Top 30 + added","Added to queue"),"Top 30 by score")) -> Top 30 by score | D19: =IF($A19="","",INDEX(Scoring!$A$5:$A$172,MATCH(15,Scoring!$AH$5:$AH$172,0))) -> hassn-alqaeri | E19: =IF($A19="","",INDEX(Scoring!$B$5:$B$172,MATCH(15,Scoring!$AH$5:$AH$172,0))) -> حسن القاعري | F19: =IF($A19="","",INDEX(Scoring!$C$5:$C$172,MATCH(15,Scoring!$AH$5:$AH$172,0))) -> Hassn Alqaeri | G19: =IF($A19="","",INDEX(Scoring!$D$5:$D$172,MATCH(15,Scoring!$AH$5:$AH$172,0))) -> مهمة OSACT7 المشتركة — LREC 2026 | H19: =IF($A19="","",INDEX(Scoring!$F$5:$F$172,MATCH(15,Scoring!$AH$5:$AH$172,0))) -> LLM | I19: =IF($A19="","",INDEX(Scoring!$G$5:$G$172,MATCH(15,Scoring!$AH$5:$AH$172,0))) -> 2026 | J19: =IF($A19="","",INDEX(Scoring!$H$5:$H$172,MATCH(15,Scoring!$AH$5:$AH$172,0))) -> n/a | K19: =IF($A19="","",INDEX(Scoring!$W$5:$W$172,MATCH(15,Scoring!$AH$5:$AH$172,0))) -> 71.1 | L19: =IF($A19="","",INDEX(Scoring!$AA$5:$AA$172,MATCH(15,Scoring!$AH$5:$AH$172,0))) -> Tier 2 – Priority | M19: =IF($A19="","",INDEX(Scoring!$AB$5:$AB$172,MATCH(15,Scoring!$AH$5:$AH$172,0))) -> Strengths: Evidence quality 4.2/5, Employer / company profile 5/5, Measurable impact 5/5. LLM track, cohort 2026; timing dated by year only. Weak on: Employment after training, Career transition. | N19: =IF($A19="","",INDEX(Scoring!$AD$5:$AD$172,MATCH(15,Scoring!$AH$5:$AH$172,0))) -> Clear draft quote with graduate; Replace GitHub avatar with real photo; Add employer logo; Confirm month-level date | O19: =IF($A19="","",INDEX(Scoring!$AE$5:$AE$172,MATCH(15,Scoring!$AH$5:$AH$172,0))) -> Draft
A20: =IF(16<=$C$3,16,"") -> 16 | B20: =IF($A20="","",INDEX(Scoring!$Z$5:$Z$172,MATCH(16,Scoring!$AH$5:$AH$172,0))) -> 16 | C20: =IF($A20="","",IF(INDEX(Scoring!$AF$5:$AF$172,MATCH(16,Scoring!$AH$5:$AH$172,0))="Yes",IF(INDEX(Scoring!$Z$5:$Z$172,MATCH(16,Scoring!$AH$5:$AH$172,0))<=Weights!$C$19,"Top 30 + added","Added to queue"),"Top 30 by score")) -> Top 30 by score | D20: =IF($A20="","",INDEX(Scoring!$A$5:$A$172,MATCH(16,Scoring!$AH$5:$AH$172,0))) -> nujud-senan | E20: =IF($A20="","",INDEX(Scoring!$B$5:$B$172,MATCH(16,Scoring!$AH$5:$AH$172,0))) -> نجود سنان | F20: =IF($A20="","",INDEX(Scoring!$C$5:$C$172,MATCH(16,Scoring!$AH$5:$AH$172,0))) -> Nujud Senan | G20: =IF($A20="","",INDEX(Scoring!$D$5:$D$172,MATCH(16,Scoring!$AH$5:$AH$172,0))) -> قمة الابتكار الكمّي — دبي (Quantum Innovation Summit) | H20: =IF($A20="","",INDEX(Scoring!$F$5:$F$172,MATCH(16,Scoring!$AH$5:$AH$172,0))) -> Data Science & AI (T5) | I20: =IF($A20="","",INDEX(Scoring!$G$5:$G$172,MATCH(16,Scoring!$AH$5:$AH$172,0))) -> 2024 | J20: =IF($A20="","",INDEX(Scoring!$H$5:$H$172,MATCH(16,Scoring!$AH$5:$AH$172,0))) -> 5 | K20: =IF($A20="","",INDEX(Scoring!$W$5:$W$172,MATCH(16,Scoring!$AH$5:$AH$172,0))) -> 71 | L20: =IF($A20="","",INDEX(Scoring!$AA$5:$AA$172,MATCH(16,Scoring!$AH$5:$AH$172,0))) -> Tier 2 – Priority | M20: =IF($A20="","",INDEX(Scoring!$AB$5:$AB$172,MATCH(16,Scoring!$AH$5:$AH$172,0))) -> Strengths: Employer / company profile 5/5, Specialization 5/5, Measurable impact 4/5. Data Science & AI (T5) track, cohort 2024; 5 months to outcome. Weak on: Career transition. | N20: =IF($A20="","",INDEX(Scoring!$AD$5:$AD$172,MATCH(16,Scoring!$AH$5:$AH$172,0))) -> Clear draft quote with graduate; Add employer logo | O20: =IF($A20="","",INDEX(Scoring!$AE$5:$AE$172,MATCH(16,Scoring!$AH$5:$AH$172,0))) -> Draft
A21: =IF(17<=$C$3,17,"") -> 17 | B21: =IF($A21="","",INDEX(Scoring!$Z$5:$Z$172,MATCH(17,Scoring!$AH$5:$AH$172,0))) -> 17 | C21: =IF($A21="","",IF(INDEX(Scoring!$AF$5:$AF$172,MATCH(17,Scoring!$AH$5:$AH$172,0))="Yes",IF(INDEX(Scoring!$Z$5:$Z$172,MATCH(17,Scoring!$AH$5:$AH$172,0))<=Weights!$C$19,"Top 30 + added","Added to queue"),"Top 30 by score")) -> Top 30 by score | D21: =IF($A21="","",INDEX(Scoring!$A$5:$A$172,MATCH(17,Scoring!$AH$5:$AH$172,0))) -> dhiyaa-alsalem | E21: =IF($A21="","",INDEX(Scoring!$B$5:$B$172,MATCH(17,Scoring!$AH$5:$AH$172,0))) -> Dhiyaa Alsalem | F21: =IF($A21="","",INDEX(Scoring!$C$5:$C$172,MATCH(17,Scoring!$AH$5:$AH$172,0))) -> Dhiyaa Alsalem | G21: =IF($A21="","",INDEX(Scoring!$D$5:$D$172,MATCH(17,Scoring!$AH$5:$AH$172,0))) -> واكب للبيانات (Wakeb Data) | H21: =IF($A21="","",INDEX(Scoring!$F$5:$F$172,MATCH(17,Scoring!$AH$5:$AH$172,0))) -> Data Science & AI (T5) | I21: =IF($A21="","",INDEX(Scoring!$G$5:$G$172,MATCH(17,Scoring!$AH$5:$AH$172,0))) -> 2024 | J21: =IF($A21="","",INDEX(Scoring!$H$5:$H$172,MATCH(17,Scoring!$AH$5:$AH$172,0))) -> 7 | K21: =IF($A21="","",INDEX(Scoring!$W$5:$W$172,MATCH(17,Scoring!$AH$5:$AH$172,0))) -> 70.7 | L21: =IF($A21="","",INDEX(Scoring!$AA$5:$AA$172,MATCH(17,Scoring!$AH$5:$AH$172,0))) -> Tier 2 – Priority | M21: =IF($A21="","",INDEX(Scoring!$AB$5:$AB$172,MATCH(17,Scoring!$AH$5:$AH$172,0))) -> Strengths: Employment after training 5/5, Employer / company profile 4/5, Specialization 5/5. Data Science & AI (T5) track, cohort 2024; 7 months to outcome. Weak on: Promotion. | N21: =IF($A21="","",INDEX(Scoring!$AD$5:$AD$172,MATCH(17,Scoring!$AH$5:$AH$172,0))) -> Clear draft quote with graduate | O21: =IF($A21="","",INDEX(Scoring!$AE$5:$AE$172,MATCH(17,Scoring!$AH$5:$AH$172,0))) -> Draft
A22: =IF(18<=$C$3,18,"") -> 18 | B22: =IF($A22="","",INDEX(Scoring!$Z$5:$Z$172,MATCH(18,Scoring!$AH$5:$AH$172,0))) -> 18 | C22: =IF($A22="","",IF(INDEX(Scoring!$AF$5:$AF$172,MATCH(18,Scoring!$AH$5:$AH$172,0))="Yes",IF(INDEX(Scoring!$Z$5:$Z$172,MATCH(18,Scoring!$AH$5:$AH$172,0))<=Weights!$C$19,"Top 30 + added","Added to queue"),"Top 30 by score")) -> Top 30 + added | D22: =IF($A22="","",INDEX(Scoring!$A$5:$A$172,MATCH(18,Scoring!$AH$5:$AH$172,0))) -> rafaa-abuazza | E22: =IF($A22="","",INDEX(Scoring!$B$5:$B$172,MATCH(18,Scoring!$AH$5:$AH$172,0))) -> رفاء أبو عزة | F22: =IF($A22="","",INDEX(Scoring!$C$5:$C$172,MATCH(18,Scoring!$AH$5:$AH$172,0))) -> Rafaa Abuazzah | G22: =IF($A22="","",INDEX(Scoring!$D$5:$D$172,MATCH(18,Scoring!$AH$5:$AH$172,0))) -> نيوم | H22: =IF($A22="","",INDEX(Scoring!$F$5:$F$172,MATCH(18,Scoring!$AH$5:$AH$172,0))) -> Data Science & AI (T5) | I22: =IF($A22="","",INDEX(Scoring!$G$5:$G$172,MATCH(18,Scoring!$AH$5:$AH$172,0))) -> 2024 | J22: =IF($A22="","",INDEX(Scoring!$H$5:$H$172,MATCH(18,Scoring!$AH$5:$AH$172,0))) -> 2 | K22: =IF($A22="","",INDEX(Scoring!$W$5:$W$172,MATCH(18,Scoring!$AH$5:$AH$172,0))) -> 70.3 | L22: =IF($A22="","",INDEX(Scoring!$AA$5:$AA$172,MATCH(18,Scoring!$AH$5:$AH$172,0))) -> Tier 2 – Priority | M22: =IF($A22="","",INDEX(Scoring!$AB$5:$AB$172,MATCH(18,Scoring!$AH$5:$AH$172,0))) -> Strengths: Employer / company profile 5/5, Employment after training 5/5, Specialization 5/5. Data Science & AI (T5) track, cohort 2024; 2 months to outcome. Weak on: Promotion. | N22: =IF($A22="","",INDEX(Scoring!$AD$5:$AD$172,MATCH(18,Scoring!$AH$5:$AH$172,0))) -> Clear draft quote with graduate | O22: =IF($A22="","",INDEX(Scoring!$AE$5:$AE$172,MATCH(18,Scoring!$AH$5:$AH$172,0))) -> Draft
A23: =IF(19<=$C$3,19,"") -> 19 | B23: =IF($A23="","",INDEX(Scoring!$Z$5:$Z$172,MATCH(19,Scoring!$AH$5:$AH$172,0))) -> 19 | C23: =IF($A23="","",IF(INDEX(Scoring!$AF$5:$AF$172,MATCH(19,Scoring!$AH$5:$AH$172,0))="Yes",IF(INDEX(Scoring!$Z$5:$Z$172,MATCH(19,Scoring!$AH$5:$AH$172,0))<=Weights!$C$19,"Top 30 + added","Added to queue"),"Top 30 by score")) -> Top 30 by score | D23: =IF($A23="","",INDEX(Scoring!$A$5:$A$172,MATCH(19,Scoring!$AH$5:$AH$172,0))) -> yasmin-alsuliman | E23: =IF($A23="","",INDEX(Scoring!$B$5:$B$172,MATCH(19,Scoring!$AH$5:$AH$172,0))) -> ياسمين آل سليمان | F23: =IF($A23="","",INDEX(Scoring!$C$5:$C$172,MATCH(19,Scoring!$AH$5:$AH$172,0))) -> Yasmin Al Suliman | G23: =IF($A23="","",INDEX(Scoring!$D$5:$D$172,MATCH(19,Scoring!$AH$5:$AH$172,0))) -> شركة المياه الوطنية (NWC) | H23: =IF($A23="","",INDEX(Scoring!$F$5:$F$172,MATCH(19,Scoring!$AH$5:$AH$172,0))) -> Data Science & AI (T5) | I23: =IF($A23="","",INDEX(Scoring!$G$5:$G$172,MATCH(19,Scoring!$AH$5:$AH$172,0))) -> 2024 | J23: =IF($A23="","",INDEX(Scoring!$H$5:$H$172,MATCH(19,Scoring!$AH$5:$AH$172,0))) -> 5 | K23: =IF($A23="","",INDEX(Scoring!$W$5:$W$172,MATCH(19,Scoring!$AH$5:$AH$172,0))) -> 69.6 | L23: =IF($A23="","",INDEX(Scoring!$AA$5:$AA$172,MATCH(19,Scoring!$AH$5:$AH$172,0))) -> Tier 2 – Priority | M23: =IF($A23="","",INDEX(Scoring!$AB$5:$AB$172,MATCH(19,Scoring!$AH$5:$AH$172,0))) -> Strengths: Employment after training 5/5, Employer / company profile 4/5, Story completeness 5/5. Data Science & AI (T5) track, cohort 2024; 5 months to outcome. Weak on: Career transition. | N23: =IF($A23="","",INDEX(Scoring!$AD$5:$AD$172,MATCH(19,Scoring!$AH$5:$AH$172,0))) -> Clear draft quote with graduate | O23: =IF($A23="","",INDEX(Scoring!$AE$5:$AE$172,MATCH(19,Scoring!$AH$5:$AH$172,0))) -> Draft
A24: =IF(20<=$C$3,20,"") -> 20 | B24: =IF($A24="","",INDEX(Scoring!$Z$5:$Z$172,MATCH(20,Scoring!$AH$5:$AH$172,0))) -> 20 | C24: =IF($A24="","",IF(INDEX(Scoring!$AF$5:$AF$172,MATCH(20,Scoring!$AH$5:$AH$172,0))="Yes",IF(INDEX(Scoring!$Z$5:$Z$172,MATCH(20,Scoring!$AH$5:$AH$172,0))<=Weights!$C$19,"Top 30 + added","Added to queue"),"Top 30 by score")) -> Top 30 by score | D24: =IF($A24="","",INDEX(Scoring!$A$5:$A$172,MATCH(20,Scoring!$AH$5:$AH$172,0))) -> rana-alshehri | E24: =IF($A24="","",INDEX(Scoring!$B$5:$B$172,MATCH(20,Scoring!$AH$5:$AH$172,0))) -> رنا الشهري | F24: =IF($A24="","",INDEX(Scoring!$C$5:$C$172,MATCH(20,Scoring!$AH$5:$AH$172,0))) -> Rana Alshehri | G24: =IF($A24="","",INDEX(Scoring!$D$5:$D$172,MATCH(20,Scoring!$AH$5:$AH$172,0))) -> مدينة الملك عبدالعزيز للعلوم والتقنية (KACST) | H24: =IF($A24="","",INDEX(Scoring!$F$5:$F$172,MATCH(20,Scoring!$AH$5:$AH$172,0))) -> GenAI / NVIDIA | I24: =IF($A24="","",INDEX(Scoring!$G$5:$G$172,MATCH(20,Scoring!$AH$5:$AH$172,0))) -> 2026 | J24: =IF($A24="","",INDEX(Scoring!$H$5:$H$172,MATCH(20,Scoring!$AH$5:$AH$172,0))) -> n/a | K24: =IF($A24="","",INDEX(Scoring!$W$5:$W$172,MATCH(20,Scoring!$AH$5:$AH$172,0))) -> 69.3 | L24: =IF($A24="","",INDEX(Scoring!$AA$5:$AA$172,MATCH(20,Scoring!$AH$5:$AH$172,0))) -> Tier 2 – Priority | M24: =IF($A24="","",INDEX(Scoring!$AB$5:$AB$172,MATCH(20,Scoring!$AH$5:$AH$172,0))) -> Strengths: Employer / company profile 5/5, Employment after training 5/5, Specialization 5/5. GenAI / NVIDIA track, cohort 2026; timing dated by year only. Weak on: Promotion, Career transition. | N24: =IF($A24="","",INDEX(Scoring!$AD$5:$AD$172,MATCH(20,Scoring!$AH$5:$AH$172,0))) -> Clear draft quote with graduate | O24: =IF($A24="","",INDEX(Scoring!$AE$5:$AE$172,MATCH(20,Scoring!$AH$5:$AH$172,0))) -> Draft
A25: =IF(21<=$C$3,21,"") -> 21 | B25: =IF($A25="","",INDEX(Scoring!$Z$5:$Z$172,MATCH(21,Scoring!$AH$5:$AH$172,0))) -> 21 | C25: =IF($A25="","",IF(INDEX(Scoring!$AF$5:$AF$172,MATCH(21,Scoring!$AH$5:$AH$172,0))="Yes",IF(INDEX(Scoring!$Z$5:$Z$172,MATCH(21,Scoring!$AH$5:$AH$172,0))<=Weights!$C$19,"Top 30 + added","Added to queue"),"Top 30 by score")) -> Top 30 by score | D25: =IF($A25="","",INDEX(Scoring!$A$5:$A$172,MATCH(21,Scoring!$AH$5:$AH$172,0))) -> hind-aljuaid | E25: =IF($A25="","",INDEX(Scoring!$B$5:$B$172,MATCH(21,Scoring!$AH$5:$AH$172,0))) -> هند الجعيد | F25: =IF($A25="","",INDEX(Scoring!$C$5:$C$172,MATCH(21,Scoring!$AH$5:$AH$172,0))) -> Hind Aljuaid | G25: =IF($A25="","",INDEX(Scoring!$D$5:$D$172,MATCH(21,Scoring!$AH$5:$AH$172,0))) -> سدايا | H25: =IF($A25="","",INDEX(Scoring!$F$5:$F$172,MATCH(21,Scoring!$AH$5:$AH$172,0))) -> GenAI / NVIDIA | I25: =IF($A25="","",INDEX(Scoring!$G$5:$G$172,MATCH(21,Scoring!$AH$5:$AH$172,0))) -> 2026 | J25: =IF($A25="","",INDEX(Scoring!$H$5:$H$172,MATCH(21,Scoring!$AH$5:$AH$172,0))) -> n/a | K25: =IF($A25="","",INDEX(Scoring!$W$5:$W$172,MATCH(21,Scoring!$AH$5:$AH$172,0))) -> 68.9 | L25: =IF($A25="","",INDEX(Scoring!$AA$5:$AA$172,MATCH(21,Scoring!$AH$5:$AH$172,0))) -> Tier 2 – Priority | M25: =IF($A25="","",INDEX(Scoring!$AB$5:$AB$172,MATCH(21,Scoring!$AH$5:$AH$172,0))) -> Strengths: Specialization 5/5, Employment after training 4/5, Measurable impact 4/5. GenAI / NVIDIA track, cohort 2026; timing dated by year only. Weak on: Promotion, Career transition. | N25: =IF($A25="","",INDEX(Scoring!$AD$5:$AD$172,MATCH(21,Scoring!$AH$5:$AH$172,0))) -> Clear draft quote with graduate | O25: =IF($A25="","",INDEX(Scoring!$AE$5:$AE$172,MATCH(21,Scoring!$AH$5:$AH$172,0))) -> Draft
A26: =IF(22<=$C$3,22,"") -> 22 | B26: =IF($A26="","",INDEX(Scoring!$Z$5:$Z$172,MATCH(22,Scoring!$AH$5:$AH$172,0))) -> 22 | C26: =IF($A26="","",IF(INDEX(Scoring!$AF$5:$AF$172,MATCH(22,Scoring!$AH$5:$AH$172,0))="Yes",IF(INDEX(Scoring!$Z$5:$Z$172,MATCH(22,Scoring!$AH$5:$AH$172,0))<=Weights!$C$19,"Top 30 + added","Added to queue"),"Top 30 by score")) -> Top 30 by score | D26: =IF($A26="","",INDEX(Scoring!$A$5:$A$172,MATCH(22,Scoring!$AH$5:$AH$172,0))) -> hussein-mohsen | E26: =IF($A26="","",INDEX(Scoring!$B$5:$B$172,MATCH(22,Scoring!$AH$5:$AH$172,0))) -> حسين محسن | F26: =IF($A26="","",INDEX(Scoring!$C$5:$C$172,MATCH(22,Scoring!$AH$5:$AH$172,0))) -> Hussain Mohsen | G26: =IF($A26="","",INDEX(Scoring!$D$5:$D$172,MATCH(22,Scoring!$AH$5:$AH$172,0))) -> أكاديمية كاوست | H26: =IF($A26="","",INDEX(Scoring!$F$5:$F$172,MATCH(22,Scoring!$AH$5:$AH$172,0))) -> Data Engineering | I26: =IF($A26="","",INDEX(Scoring!$G$5:$G$172,MATCH(22,Scoring!$AH$5:$AH$172,0))) -> 2025 | J26: =IF($A26="","",INDEX(Scoring!$H$5:$H$172,MATCH(22,Scoring!$AH$5:$AH$172,0))) -> n/a | K26: =IF($A26="","",INDEX(Scoring!$W$5:$W$172,MATCH(22,Scoring!$AH$5:$AH$172,0))) -> 68.7 | L26: =IF($A26="","",INDEX(Scoring!$AA$5:$AA$172,MATCH(22,Scoring!$AH$5:$AH$172,0))) -> Tier 2 – Priority | M26: =IF($A26="","",INDEX(Scoring!$AB$5:$AB$172,MATCH(22,Scoring!$AH$5:$AH$172,0))) -> Strengths: Employment after training 5/5, Employer / company profile 4/5, Specialization 5/5. Data Engineering track, cohort 2025; timing dated by year only. Weak on: Promotion. | N26: =IF($A26="","",INDEX(Scoring!$AD$5:$AD$172,MATCH(22,Scoring!$AH$5:$AH$172,0))) -> Clear draft quote with graduate; Confirm month-level date | O26: =IF($A26="","",INDEX(Scoring!$AE$5:$AE$172,MATCH(22,Scoring!$AH$5:$AH$172,0))) -> Draft
A27: =IF(23<=$C$3,23,"") -> 23 | B27: =IF($A27="","",INDEX(Scoring!$Z$5:$Z$172,MATCH(23,Scoring!$AH$5:$AH$172,0))) -> 23 | C27: =IF($A27="","",IF(INDEX(Scoring!$AF$5:$AF$172,MATCH(23,Scoring!$AH$5:$AH$172,0))="Yes",IF(INDEX(Scoring!$Z$5:$Z$172,MATCH(23,Scoring!$AH$5:$AH$172,0))<=Weights!$C$19,"Top 30 + added","Added to queue"),"Top 30 by score")) -> Top 30 by score | D27: =IF($A27="","",INDEX(Scoring!$A$5:$A$172,MATCH(23,Scoring!$AH$5:$AH$172,0))) -> meead-alshaibani | E27: =IF($A27="","",INDEX(Scoring!$B$5:$B$172,MATCH(23,Scoring!$AH$5:$AH$172,0))) -> ميعاد الشيباني | F27: =IF($A27="","",INDEX(Scoring!$C$5:$C$172,MATCH(23,Scoring!$AH$5:$AH$172,0))) -> Meead Alshaibani | G27: =IF($A27="","",INDEX(Scoring!$D$5:$D$172,MATCH(23,Scoring!$AH$5:$AH$172,0))) -> صندوق التنمية العقارية (REDF) | H27: =IF($A27="","",INDEX(Scoring!$F$5:$F$172,MATCH(23,Scoring!$AH$5:$AH$172,0))) -> GenAI / NVIDIA | I27: =IF($A27="","",INDEX(Scoring!$G$5:$G$172,MATCH(23,Scoring!$AH$5:$AH$172,0))) -> 2026 | J27: =IF($A27="","",INDEX(Scoring!$H$5:$H$172,MATCH(23,Scoring!$AH$5:$AH$172,0))) -> 4 | K27: =IF($A27="","",INDEX(Scoring!$W$5:$W$172,MATCH(23,Scoring!$AH$5:$AH$172,0))) -> 68.7 | L27: =IF($A27="","",INDEX(Scoring!$AA$5:$AA$172,MATCH(23,Scoring!$AH$5:$AH$172,0))) -> Tier 2 – Priority | M27: =IF($A27="","",INDEX(Scoring!$AB$5:$AB$172,MATCH(23,Scoring!$AH$5:$AH$172,0))) -> Strengths: Employment after training 5/5, Employer / company profile 4/5, Specialization 5/5. GenAI / NVIDIA track, cohort 2026; 4 months to outcome. Weak on: Promotion, Career transition. | N27: =IF($A27="","",INDEX(Scoring!$AD$5:$AD$172,MATCH(23,Scoring!$AH$5:$AH$172,0))) -> Clear draft quote with graduate | O27: =IF($A27="","",INDEX(Scoring!$AE$5:$AE$172,MATCH(23,Scoring!$AH$5:$AH$172,0))) -> Draft
A28: =IF(24<=$C$3,24,"") -> 24 | B28: =IF($A28="","",INDEX(Scoring!$Z$5:$Z$172,MATCH(24,Scoring!$AH$5:$AH$172,0))) -> 24 | C28: =IF($A28="","",IF(INDEX(Scoring!$AF$5:$AF$172,MATCH(24,Scoring!$AH$5:$AH$172,0))="Yes",IF(INDEX(Scoring!$Z$5:$Z$172,MATCH(24,Scoring!$AH$5:$AH$172,0))<=Weights!$C$19,"Top 30 + added","Added to queue"),"Top 30 by score")) -> Top 30 + added | D28: =IF($A28="","",INDEX(Scoring!$A$5:$A$172,MATCH(24,Scoring!$AH$5:$AH$172,0))) -> faris-almuteri | E28: =IF($A28="","",INDEX(Scoring!$B$5:$B$172,MATCH(24,Scoring!$AH$5:$AH$172,0))) -> فارس المطيري | F28: =IF($A28="","",INDEX(Scoring!$C$5:$C$172,MATCH(24,Scoring!$AH$5:$AH$172,0))) -> Faris Al Muteri | G28: =IF($A28="","",INDEX(Scoring!$D$5:$D$172,MATCH(24,Scoring!$AH$5:$AH$172,0))) -> مركز الملك عبدالله العالمي للأبحاث الطبية KAIMRC | H28: =IF($A28="","",INDEX(Scoring!$F$5:$F$172,MATCH(24,Scoring!$AH$5:$AH$172,0))) -> Advanced AI Pathways | I28: =IF($A28="","",INDEX(Scoring!$G$5:$G$172,MATCH(24,Scoring!$AH$5:$AH$172,0))) -> 2024 | J28: =IF($A28="","",INDEX(Scoring!$H$5:$H$172,MATCH(24,Scoring!$AH$5:$AH$172,0))) -> 7 | K28: =IF($A28="","",INDEX(Scoring!$W$5:$W$172,MATCH(24,Scoring!$AH$5:$AH$172,0))) -> 68.4 | L28: =IF($A28="","",INDEX(Scoring!$AA$5:$AA$172,MATCH(24,Scoring!$AH$5:$AH$172,0))) -> Tier 2 – Priority | M28: =IF($A28="","",INDEX(Scoring!$AB$5:$AB$172,MATCH(24,Scoring!$AH$5:$AH$172,0))) -> Strengths: Employer / company profile 5/5, Story completeness 4.8/5, Specialization 4/5. Advanced AI Pathways track, cohort 2024; 7 months to outcome. Weak on: Career transition. | N28: =IF($A28="","",INDEX(Scoring!$AD$5:$AD$172,MATCH(24,Scoring!$AH$5:$AH$172,0))) -> Clear draft quote with graduate | O28: =IF($A28="","",INDEX(Scoring!$AE$5:$AE$172,MATCH(24,Scoring!$AH$5:$AH$172,0))) -> Draft
A29: =IF(25<=$C$3,25,"") -> 25 | B29: =IF($A29="","",INDEX(Scoring!$Z$5:$Z$172,MATCH(25,Scoring!$AH$5:$AH$172,0))) -> 25 | C29: =IF($A29="","",IF(INDEX(Scoring!$AF$5:$AF$172,MATCH(25,Scoring!$AH$5:$AH$172,0))="Yes",IF(INDEX(Scoring!$Z$5:$Z$172,MATCH(25,Scoring!$AH$5:$AH$172,0))<=Weights!$C$19,"Top 30 + added","Added to queue"),"Top 30 by score")) -> Top 30 by score | D29: =IF($A29="","",INDEX(Scoring!$A$5:$A$172,MATCH(25,Scoring!$AH$5:$AH$172,0))) -> wadha-almattar | E29: =IF($A29="","",INDEX(Scoring!$B$5:$B$172,MATCH(25,Scoring!$AH$5:$AH$172,0))) -> د. وضحة المطر | F29: =IF($A29="","",INDEX(Scoring!$C$5:$C$172,MATCH(25,Scoring!$AH$5:$AH$172,0))) -> Dr. Wadha Almattar | G29: =IF($A29="","",INDEX(Scoring!$D$5:$D$172,MATCH(25,Scoring!$AH$5:$AH$172,0))) -> جامعة الإمام عبدالرحمن بن فيصل | H29: =IF($A29="","",INDEX(Scoring!$F$5:$F$172,MATCH(25,Scoring!$AH$5:$AH$172,0))) -> GenAI / NVIDIA | I29: =IF($A29="","",INDEX(Scoring!$G$5:$G$172,MATCH(25,Scoring!$AH$5:$AH$172,0))) -> 2025 | J29: =IF($A29="","",INDEX(Scoring!$H$5:$H$172,MATCH(25,Scoring!$AH$5:$AH$172,0))) -> 6 | K29: =IF($A29="","",INDEX(Scoring!$W$5:$W$172,MATCH(25,Scoring!$AH$5:$AH$172,0))) -> 68.4 | L29: =IF($A29="","",INDEX(Scoring!$AA$5:$AA$172,MATCH(25,Scoring!$AH$5:$AH$172,0))) -> Tier 2 – Priority | M29: =IF($A29="","",INDEX(Scoring!$AB$5:$AB$172,MATCH(25,Scoring!$AH$5:$AH$172,0))) -> Strengths: Employer / company profile 4/5, Achievements 5/5, Strategic relevance 5/5. GenAI / NVIDIA track, cohort 2025; 6 months to outcome. Weak on: Career transition. | N29: =IF($A29="","",INDEX(Scoring!$AD$5:$AD$172,MATCH(25,Scoring!$AH$5:$AH$172,0))) -> Clear draft quote with graduate | O29: =IF($A29="","",INDEX(Scoring!$AE$5:$AE$172,MATCH(25,Scoring!$AH$5:$AH$172,0))) -> Draft
A30: =IF(26<=$C$3,26,"") -> 26 | B30: =IF($A30="","",INDEX(Scoring!$Z$5:$Z$172,MATCH(26,Scoring!$AH$5:$AH$172,0))) -> 26 | C30: =IF($A30="","",IF(INDEX(Scoring!$AF$5:$AF$172,MATCH(26,Scoring!$AH$5:$AH$172,0))="Yes",IF(INDEX(Scoring!$Z$5:$Z$172,MATCH(26,Scoring!$AH$5:$AH$172,0))<=Weights!$C$19,"Top 30 + added","Added to queue"),"Top 30 by score")) -> Top 30 by score | D30: =IF($A30="","",INDEX(Scoring!$A$5:$A$172,MATCH(26,Scoring!$AH$5:$AH$172,0))) -> dimah-albunayyih | E30: =IF($A30="","",INDEX(Scoring!$B$5:$B$172,MATCH(26,Scoring!$AH$5:$AH$172,0))) -> ديمة البنية | F30: =IF($A30="","",INDEX(Scoring!$C$5:$C$172,MATCH(26,Scoring!$AH$5:$AH$172,0))) -> Dimah Albunayyih | G30: =IF($A30="","",INDEX(Scoring!$D$5:$D$172,MATCH(26,Scoring!$AH$5:$AH$172,0))) -> شركة علم | H30: =IF($A30="","",INDEX(Scoring!$F$5:$F$172,MATCH(26,Scoring!$AH$5:$AH$172,0))) -> Data Science & AI (T5) | I30: =IF($A30="","",INDEX(Scoring!$G$5:$G$172,MATCH(26,Scoring!$AH$5:$AH$172,0))) -> 2021 | J30: =IF($A30="","",INDEX(Scoring!$H$5:$H$172,MATCH(26,Scoring!$AH$5:$AH$172,0))) -> 4 | K30: =IF($A30="","",INDEX(Scoring!$W$5:$W$172,MATCH(26,Scoring!$AH$5:$AH$172,0))) -> 68.2 | L30: =IF($A30="","",INDEX(Scoring!$AA$5:$AA$172,MATCH(26,Scoring!$AH$5:$AH$172,0))) -> Tier 2 – Priority | M30: =IF($A30="","",INDEX(Scoring!$AB$5:$AB$172,MATCH(26,Scoring!$AH$5:$AH$172,0))) -> Strengths: Employer / company profile 5/5, Employment after training 5/5, Promotion 5/5. Data Science & AI (T5) track, cohort 2021; 4 months to outcome. Weak on: Career transition. | N30: =IF($A30="","",INDEX(Scoring!$AD$5:$AD$172,MATCH(26,Scoring!$AH$5:$AH$172,0))) -> Clear draft quote with graduate | O30: =IF($A30="","",INDEX(Scoring!$AE$5:$AE$172,MATCH(26,Scoring!$AH$5:$AH$172,0))) -> Draft
A31: =IF(27<=$C$3,27,"") -> 27 | B31: =IF($A31="","",INDEX(Scoring!$Z$5:$Z$172,MATCH(27,Scoring!$AH$5:$AH$172,0))) -> 27 | C31: =IF($A31="","",IF(INDEX(Scoring!$AF$5:$AF$172,MATCH(27,Scoring!$AH$5:$AH$172,0))="Yes",IF(INDEX(Scoring!$Z$5:$Z$172,MATCH(27,Scoring!$AH$5:$AH$172,0))<=Weights!$C$19,"Top 30 + added","Added to queue"),"Top 30 by score")) -> Top 30 by score | D31: =IF($A31="","",INDEX(Scoring!$A$5:$A$172,MATCH(27,Scoring!$AH$5:$AH$172,0))) -> radhyah-alzubaidi | E31: =IF($A31="","",INDEX(Scoring!$B$5:$B$172,MATCH(27,Scoring!$AH$5:$AH$172,0))) -> رضيه الزبيدي | F31: =IF($A31="","",INDEX(Scoring!$C$5:$C$172,MATCH(27,Scoring!$AH$5:$AH$172,0))) -> Radhyah Alzubaidi | G31: =IF($A31="","",INDEX(Scoring!$D$5:$D$172,MATCH(27,Scoring!$AH$5:$AH$172,0))) -> ماستر ووركس (Master Works) | H31: =IF($A31="","",INDEX(Scoring!$F$5:$F$172,MATCH(27,Scoring!$AH$5:$AH$172,0))) -> LLM | I31: =IF($A31="","",INDEX(Scoring!$G$5:$G$172,MATCH(27,Scoring!$AH$5:$AH$172,0))) -> 2024 | J31: =IF($A31="","",INDEX(Scoring!$H$5:$H$172,MATCH(27,Scoring!$AH$5:$AH$172,0))) -> 7 | K31: =IF($A31="","",INDEX(Scoring!$W$5:$W$172,MATCH(27,Scoring!$AH$5:$AH$172,0))) -> 68.1 | L31: =IF($A31="","",INDEX(Scoring!$AA$5:$AA$172,MATCH(27,Scoring!$AH$5:$AH$172,0))) -> Tier 2 – Priority | M31: =IF($A31="","",INDEX(Scoring!$AB$5:$AB$172,MATCH(27,Scoring!$AH$5:$AH$172,0))) -> Strengths: Employment after training 5/5, Employer / company profile 4/5, Specialization 5/5. LLM track, cohort 2024; 7 months to outcome. Weak on: Career transition. | N31: =IF($A31="","",INDEX(Scoring!$AD$5:$AD$172,MATCH(27,Scoring!$AH$5:$AH$172,0))) -> Clear draft quote with graduate; Non-photo image (avatar/monogram) | O31: =IF($A31="","",INDEX(Scoring!$AE$5:$AE$172,MATCH(27,Scoring!$AH$5:$AH$172,0))) -> Draft
A32: =IF(28<=$C$3,28,"") -> 28 | B32: =IF($A32="","",INDEX(Scoring!$Z$5:$Z$172,MATCH(28,Scoring!$AH$5:$AH$172,0))) -> 28 | C32: =IF($A32="","",IF(INDEX(Scoring!$AF$5:$AF$172,MATCH(28,Scoring!$AH$5:$AH$172,0))="Yes",IF(INDEX(Scoring!$Z$5:$Z$172,MATCH(28,Scoring!$AH$5:$AH$172,0))<=Weights!$C$19,"Top 30 + added","Added to queue"),"Top 30 by score")) -> Top 30 by score | D32: =IF($A32="","",INDEX(Scoring!$A$5:$A$172,MATCH(28,Scoring!$AH$5:$AH$172,0))) -> ranya-alkahtani | E32: =IF($A32="","",INDEX(Scoring!$B$5:$B$172,MATCH(28,Scoring!$AH$5:$AH$172,0))) -> رانيا القحطاني | F32: =IF($A32="","",INDEX(Scoring!$C$5:$C$172,MATCH(28,Scoring!$AH$5:$AH$172,0))) -> Ranya A. Alkahtani | G32: =IF($A32="","",INDEX(Scoring!$D$5:$D$172,MATCH(28,Scoring!$AH$5:$AH$172,0))) -> هيوماين (HUMAIN) | H32: =IF($A32="","",INDEX(Scoring!$F$5:$F$172,MATCH(28,Scoring!$AH$5:$AH$172,0))) -> Data Science & AI (T5) | I32: =IF($A32="","",INDEX(Scoring!$G$5:$G$172,MATCH(28,Scoring!$AH$5:$AH$172,0))) -> 2021 | J32: =IF($A32="","",INDEX(Scoring!$H$5:$H$172,MATCH(28,Scoring!$AH$5:$AH$172,0))) -> 0 | K32: =IF($A32="","",INDEX(Scoring!$W$5:$W$172,MATCH(28,Scoring!$AH$5:$AH$172,0))) -> 68 | L32: =IF($A32="","",INDEX(Scoring!$AA$5:$AA$172,MATCH(28,Scoring!$AH$5:$AH$172,0))) -> Tier 2 – Priority | M32: =IF($A32="","",INDEX(Scoring!$AB$5:$AB$172,MATCH(28,Scoring!$AH$5:$AH$172,0))) -> Strengths: Employer / company profile 5/5, Specialization 5/5, Employment after training 4/5. Data Science & AI (T5) track, cohort 2021; outcome in completion month. | N32: =IF($A32="","",INDEX(Scoring!$AD$5:$AD$172,MATCH(28,Scoring!$AH$5:$AH$172,0))) -> Clear draft quote with graduate; Hire in completion month — check subsequence | O32: =IF($A32="","",INDEX(Scoring!$AE$5:$AE$172,MATCH(28,Scoring!$AH$5:$AH$172,0))) -> Draft
A33: =IF(29<=$C$3,29,"") -> 29 | B33: =IF($A33="","",INDEX(Scoring!$Z$5:$Z$172,MATCH(29,Scoring!$AH$5:$AH$172,0))) -> 29 | C33: =IF($A33="","",IF(INDEX(Scoring!$AF$5:$AF$172,MATCH(29,Scoring!$AH$5:$AH$172,0))="Yes",IF(INDEX(Scoring!$Z$5:$Z$172,MATCH(29,Scoring!$AH$5:$AH$172,0))<=Weights!$C$19,"Top 30 + added","Added to queue"),"Top 30 by score")) -> Top 30 by score | D33: =IF($A33="","",INDEX(Scoring!$A$5:$A$172,MATCH(29,Scoring!$AH$5:$AH$172,0))) -> bayan-albaqami | E33: =IF($A33="","",INDEX(Scoring!$B$5:$B$172,MATCH(29,Scoring!$AH$5:$AH$172,0))) -> Bayan Albaqami | F33: =IF($A33="","",INDEX(Scoring!$C$5:$C$172,MATCH(29,Scoring!$AH$5:$AH$172,0))) -> Bayan Albaqami | G33: =IF($A33="","",INDEX(Scoring!$D$5:$D$172,MATCH(29,Scoring!$AH$5:$AH$172,0))) -> بنك التنمية الاجتماعية | H33: =IF($A33="","",INDEX(Scoring!$F$5:$F$172,MATCH(29,Scoring!$AH$5:$AH$172,0))) -> Data Engineering | I33: =IF($A33="","",INDEX(Scoring!$G$5:$G$172,MATCH(29,Scoring!$AH$5:$AH$172,0))) -> 2025 | J33: =IF($A33="","",INDEX(Scoring!$H$5:$H$172,MATCH(29,Scoring!$AH$5:$AH$172,0))) -> 4 | K33: =IF($A33="","",INDEX(Scoring!$W$5:$W$172,MATCH(29,Scoring!$AH$5:$AH$172,0))) -> 67.7 | L33: =IF($A33="","",INDEX(Scoring!$AA$5:$AA$172,MATCH(29,Scoring!$AH$5:$AH$172,0))) -> Tier 2 – Priority | M33: =IF($A33="","",INDEX(Scoring!$AB$5:$AB$172,MATCH(29,Scoring!$AH$5:$AH$172,0))) -> Strengths: Employment after training 5/5, Employer / company profile 4/5, Story completeness 5/5. Data Engineering track, cohort 2025; 4 months to outcome. Weak on: Promotion, Career transition. | N33: =IF($A33="","",INDEX(Scoring!$AD$5:$AD$172,MATCH(29,Scoring!$AH$5:$AH$172,0))) -> Clear draft quote with graduate | O33: =IF($A33="","",INDEX(Scoring!$AE$5:$AE$172,MATCH(29,Scoring!$AH$5:$AH$172,0))) -> Draft
A34: =IF(30<=$C$3,30,"") -> 30 | B34: =IF($A34="","",INDEX(Scoring!$Z$5:$Z$172,MATCH(30,Scoring!$AH$5:$AH$172,0))) -> 30 | C34: =IF($A34="","",IF(INDEX(Scoring!$AF$5:$AF$172,MATCH(30,Scoring!$AH$5:$AH$172,0))="Yes",IF(INDEX(Scoring!$Z$5:$Z$172,MATCH(30,Scoring!$AH$5:$AH$172,0))<=Weights!$C$19,"Top 30 + added","Added to queue"),"Top 30 by score")) -> Top 30 by score | D34: =IF($A34="","",INDEX(Scoring!$A$5:$A$172,MATCH(30,Scoring!$AH$5:$AH$172,0))) -> mohammed-albrayh | E34: =IF($A34="","",INDEX(Scoring!$B$5:$B$172,MATCH(30,Scoring!$AH$5:$AH$172,0))) -> محمد البريح | F34: =IF($A34="","",INDEX(Scoring!$C$5:$C$172,MATCH(30,Scoring!$AH$5:$AH$172,0))) -> Mohammed Albrayh | G34: =IF($A34="","",INDEX(Scoring!$D$5:$D$172,MATCH(30,Scoring!$AH$5:$AH$172,0))) -> سدايا | H34: =IF($A34="","",INDEX(Scoring!$F$5:$F$172,MATCH(30,Scoring!$AH$5:$AH$172,0))) -> LLM | I34: =IF($A34="","",INDEX(Scoring!$G$5:$G$172,MATCH(30,Scoring!$AH$5:$AH$172,0))) -> 2024 | J34: =IF($A34="","",INDEX(Scoring!$H$5:$H$172,MATCH(30,Scoring!$AH$5:$AH$172,0))) -> 3 | K34: =IF($A34="","",INDEX(Scoring!$W$5:$W$172,MATCH(30,Scoring!$AH$5:$AH$172,0))) -> 67.7 | L34: =IF($A34="","",INDEX(Scoring!$AA$5:$AA$172,MATCH(30,Scoring!$AH$5:$AH$172,0))) -> Tier 2 – Priority | M34: =IF($A34="","",INDEX(Scoring!$AB$5:$AB$172,MATCH(30,Scoring!$AH$5:$AH$172,0))) -> Strengths: Specialization 5/5, Employment after training 4/5, Story completeness 4.8/5. LLM track, cohort 2024; 3 months to outcome. Weak on: Promotion. | N34: =IF($A34="","",INDEX(Scoring!$AD$5:$AD$172,MATCH(30,Scoring!$AH$5:$AH$172,0))) -> Clear draft quote with graduate | O34: =IF($A34="","",INDEX(Scoring!$AE$5:$AE$172,MATCH(30,Scoring!$AH$5:$AH$172,0))) -> Draft
A35: =IF(31<=$C$3,31,"") -> 31 | B35: =IF($A35="","",INDEX(Scoring!$Z$5:$Z$172,MATCH(31,Scoring!$AH$5:$AH$172,0))) -> 31 | C35: =IF($A35="","",IF(INDEX(Scoring!$AF$5:$AF$172,MATCH(31,Scoring!$AH$5:$AH$172,0))="Yes",IF(INDEX(Scoring!$Z$5:$Z$172,MATCH(31,Scoring!$AH$5:$AH$172,0))<=Weights!$C$19,"Top 30 + added","Added to queue"),"Top 30 by score")) -> Added to queue | D35: =IF($A35="","",INDEX(Scoring!$A$5:$A$172,MATCH(31,Scoring!$AH$5:$AH$172,0))) -> majid-almadani | E35: =IF($A35="","",INDEX(Scoring!$B$5:$B$172,MATCH(31,Scoring!$AH$5:$AH$172,0))) -> ماجد المدني | F35: =IF($A35="","",INDEX(Scoring!$C$5:$C$172,MATCH(31,Scoring!$AH$5:$AH$172,0))) -> Majid Almadani | G35: =IF($A35="","",INDEX(Scoring!$D$5:$D$172,MATCH(31,Scoring!$AH$5:$AH$172,0))) -> البنك السعودي للاستثمار (SAIB) | H35: =IF($A35="","",INDEX(Scoring!$F$5:$F$172,MATCH(31,Scoring!$AH$5:$AH$172,0))) -> Data Science & AI (T5) | I35: =IF($A35="","",INDEX(Scoring!$G$5:$G$172,MATCH(31,Scoring!$AH$5:$AH$172,0))) -> 2024 | J35: =IF($A35="","",INDEX(Scoring!$H$5:$H$172,MATCH(31,Scoring!$AH$5:$AH$172,0))) -> 12 | K35: =IF($A35="","",INDEX(Scoring!$W$5:$W$172,MATCH(31,Scoring!$AH$5:$AH$172,0))) -> 67.4 | L35: =IF($A35="","",INDEX(Scoring!$AA$5:$AA$172,MATCH(31,Scoring!$AH$5:$AH$172,0))) -> Tier 2 – Priority | M35: =IF($A35="","",INDEX(Scoring!$AB$5:$AB$172,MATCH(31,Scoring!$AH$5:$AH$172,0))) -> Strengths: Employment after training 5/5, Employer / company profile 4/5, Specialization 5/5. Data Science & AI (T5) track, cohort 2024; 12 months to outcome. Weak on: Time since training, Career transition. | N35: =IF($A35="","",INDEX(Scoring!$AD$5:$AD$172,MATCH(31,Scoring!$AH$5:$AH$172,0))) -> Clear draft quote with graduate; Add employer logo | O35: =IF($A35="","",INDEX(Scoring!$AE$5:$AE$172,MATCH(31,Scoring!$AH$5:$AH$172,0))) -> Draft
A36: =IF(32<=$C$3,32,"") -> 32 | B36: =IF($A36="","",INDEX(Scoring!$Z$5:$Z$172,MATCH(32,Scoring!$AH$5:$AH$172,0))) -> 32 | C36: =IF($A36="","",IF(INDEX(Scoring!$AF$5:$AF$172,MATCH(32,Scoring!$AH$5:$AH$172,0))="Yes",IF(INDEX(Scoring!$Z$5:$Z$172,MATCH(32,Scoring!$AH$5:$AH$172,0))<=Weights!$C$19,"Top 30 + added","Added to queue"),"Top 30 by score")) -> Added to queue | D36: =IF($A36="","",INDEX(Scoring!$A$5:$A$172,MATCH(32,Scoring!$AH$5:$AH$172,0))) -> mazen-alkhodairi | E36: =IF($A36="","",INDEX(Scoring!$B$5:$B$172,MATCH(32,Scoring!$AH$5:$AH$172,0))) -> مازن الخضيري | F36: =IF($A36="","",INDEX(Scoring!$C$5:$C$172,MATCH(32,Scoring!$AH$5:$AH$172,0))) -> Mazen Alkhodairi | G36: =IF($A36="","",INDEX(Scoring!$D$5:$D$172,MATCH(32,Scoring!$AH$5:$AH$172,0))) -> شركة الإلكترونيات المتقدمة (SAMI Advanced Electronics) | H36: =IF($A36="","",INDEX(Scoring!$F$5:$F$172,MATCH(32,Scoring!$AH$5:$AH$172,0))) -> Advanced AI Pathways | I36: =IF($A36="","",INDEX(Scoring!$G$5:$G$172,MATCH(32,Scoring!$AH$5:$AH$172,0))) -> 2025 | J36: =IF($A36="","",INDEX(Scoring!$H$5:$H$172,MATCH(32,Scoring!$AH$5:$AH$172,0))) -> 9 | K36: =IF($A36="","",INDEX(Scoring!$W$5:$W$172,MATCH(32,Scoring!$AH$5:$AH$172,0))) -> 67.3 | L36: =IF($A36="","",INDEX(Scoring!$AA$5:$AA$172,MATCH(32,Scoring!$AH$5:$AH$172,0))) -> Tier 2 – Priority | M36: =IF($A36="","",INDEX(Scoring!$AB$5:$AB$172,MATCH(32,Scoring!$AH$5:$AH$172,0))) -> Strengths: Employment after training 5/5, Employer / company profile 4/5, Story completeness 5/5. Advanced AI Pathways track, cohort 2025; 9 months to outcome. Weak on: Promotion. | N36: =IF($A36="","",INDEX(Scoring!$AD$5:$AD$172,MATCH(32,Scoring!$AH$5:$AH$172,0))) -> Clear draft quote with graduate | O36: =IF($A36="","",INDEX(Scoring!$AE$5:$AE$172,MATCH(32,Scoring!$AH$5:$AH$172,0))) -> Draft
