Workbook

Sheet Summary
A1: Migration mapping — summary
A2: Counts are formulas over the Mapping sheet. Source: migration/migration-mapping.csv (scripts/migration/build_mapping.py).
A4: Action | B4: Items | C4: MB
A5: Migrate | B5: =COUNTIF(Mapping!$H$2:$H$2146,A5) -> 231 | C5: =SUMIF(Mapping!$H$2:$H$2146,A5,Mapping!$D$2:$D$2146)/1000000 -> 69.133672
A6: Rename | B6: =COUNTIF(Mapping!$H$2:$H$2146,A6) -> 49 | C6: =SUMIF(Mapping!$H$2:$H$2146,A6,Mapping!$D$2:$D$2146)/1000000 -> 11.697424
A7: Extract | B7: =COUNTIF(Mapping!$H$2:$H$2146,A7) -> 1133 | C7: =SUMIF(Mapping!$H$2:$H$2146,A7,Mapping!$D$2:$D$2146)/1000000 -> 175.17837
A8: Convert | B8: =COUNTIF(Mapping!$H$2:$H$2146,A8) -> 26 | C8: =SUMIF(Mapping!$H$2:$H$2146,A8,Mapping!$D$2:$D$2146)/1000000 -> 5.084139
A9: Archive | B9: =COUNTIF(Mapping!$H$2:$H$2146,A9) -> 5 | C9: =SUMIF(Mapping!$H$2:$H$2146,A9,Mapping!$D$2:$D$2146)/1000000 -> 11.959312
A10: Duplicate | B10: =COUNTIF(Mapping!$H$2:$H$2146,A10) -> 389 | C10: =SUMIF(Mapping!$H$2:$H$2146,A10,Mapping!$D$2:$D$2146)/1000000 -> 105.49736
A11: Exclude | B11: =COUNTIF(Mapping!$H$2:$H$2146,A11) -> 298 | C11: =SUMIF(Mapping!$H$2:$H$2146,A11,Mapping!$D$2:$D$2146)/1000000 -> 10.483076
A12: Container | B12: =COUNTIF(Mapping!$H$2:$H$2146,A12) -> 14 | C12: =SUMIF(Mapping!$H$2:$H$2146,A12,Mapping!$D$2:$D$2146)/1000000 -> 130.05044
A13: Total | B13: =SUM(B5:B12) -> 2145 | C13: =SUM(C5:C12) -> 519.08379
A15: Category | B15: Items | C15: MB
A16: Ready | B16: =COUNTIF(Mapping!$I$2:$I$2146,A16) -> 1426 | C16: =SUMIF(Mapping!$I$2:$I$2146,A16,Mapping!$D$2:$D$2146)/1000000 -> 382.52318
A17: Needs Review | B17: =COUNTIF(Mapping!$I$2:$I$2146,A17) -> 23 | C17: =SUMIF(Mapping!$I$2:$I$2146,A17,Mapping!$D$2:$D$2146)/1000000 -> 15.510094
A18: Security Concern | B18: =COUNTIF(Mapping!$I$2:$I$2146,A18) -> 6 | C18: =SUMIF(Mapping!$I$2:$I$2146,A18,Mapping!$D$2:$D$2146)/1000000 -> 0.784122
A19: Duplicate | B19: =COUNTIF(Mapping!$I$2:$I$2146,A19) -> 391 | C19: =SUMIF(Mapping!$I$2:$I$2146,A19,Mapping!$D$2:$D$2146)/1000000 -> 109.62648
A20: Obsolete | B20: =COUNTIF(Mapping!$I$2:$I$2146,A20) -> 299 | C20: =SUMIF(Mapping!$I$2:$I$2146,A20,Mapping!$D$2:$D$2146)/1000000 -> 10.639914
A21: Total | B21: =SUM(B16:B20) -> 2145 | C21: =SUM(C16:C20) -> 519.08379
A23: Storage | B23: Items | C23: MB
A24: git | B24: =COUNTIF(Mapping!$J$2:$J$2146,A24) -> 1120 | C24: =SUMIF(Mapping!$J$2:$J$2146,A24,Mapping!$D$2:$D$2146)/1000000 -> 78.912332
A25: git-lfs | B25: =COUNTIF(Mapping!$J$2:$J$2146,A25) -> 324 | C25: =SUMIF(Mapping!$J$2:$J$2146,A25,Mapping!$D$2:$D$2146)/1000000 -> 194.14058
A26: Total | B26: =SUM(B24:B25) -> 1444 | C26: =SUM(C24:C25) -> 273.05292

Sheet Mapping
A1: source_path | B1: archive_member | C1: sha256 | D1: size_bytes | E1: course_code | F1: content_type | G1: target_path | H1: action | I1: category | J1: storage | K1: notes
A2: AI Engineer Track/AI Engineering Capstone — Production GenAI System/INSTRUCTOR_PACKAGE.md | C2: 9e74406ad5697e6d6c7124571d93630badfc2fd3e66c972a2e74ea78cebe144c | D2: 169710 | E2: SDA-AIE-390 | F2: Instructor guide | G2: catalog/ai-engineer/SDA-AIE-390-ai-engineering-capstone-production-genai-system/instructor-guide.md | H2: Convert | I2: Ready | J2: git | K2: Body preserved verbatim under a governance header
A3: AI Engineer Track/AI Performance, Scalability and Cost Optimization/INSTRUCTOR_PACKAGE.md | C3: 6718a403aa64450f21f80ad3831694663ea0f3c124c25e37abf9d326c847886f | D3: 174645 | E3: SDA-AIE-314 | F3: Instructor guide | G3: catalog/ai-engineer/SDA-AIE-314-ai-performance-scalability-and-cost-optimization/instructor-guide.md | H3: Convert | I3: Ready | J3: git | K3: Body preserved verbatim under a governance header
A4: AI Engineer Track/AI Security, Guardrails and Red Teaming/INSTRUCTOR_PACKAGE.md | C4: 5327db71cbf725292a33c1b10a2639df52c0ec8b3940753adc13ee530e78ccba | D4: 169683 | E4: SDA-AIE-313 | F4: Instructor guide | G4: catalog/ai-engineer/SDA-AIE-313-ai-security-guardrails-and-red-teaming/instructor-guide.md | H4: Convert | I4: Ready | J4: git | K4: Body preserved verbatim under a governance header
A5: AI Engineer Track/Advanced Agentic AI Systems Engineering/01_Training_Deck/SDA-AIE-311_Agentic_AI_Systems_Engineering_Deck.pdf | C5: 0f677a22fbace5ab416206900145bb94018f1162c17bfe097b3958063b893855 | D5: 2620813 | E5: SDA-AIE-311 | F5: Slides | G5: catalog/ai-engineer/SDA-AIE-311-agentic-ai-systems-engineering/slides/SDA-AIE-311_Agentic_AI_Systems_Engineering_Deck.pdf | H5: Migrate | I5: Ready | J5: git-lfs
A6: AI Engineer Track/Advanced Agentic AI Systems Engineering/01_Training_Deck/SDA-AIE-311_Agentic_AI_Systems_Engineering_Deck.pptx | C6: 7205be374a1ff9475c25efe2a51114323bc10dfd09900c005b3aba97759072f3 | D6: 6972619 | E6: SDA-AIE-311 | F6: Slides | G6: catalog/ai-engineer/SDA-AIE-311-agentic-ai-systems-engineering/slides/SDA-AIE-311_Agentic_AI_Systems_Engineering_Deck.pptx | H6: Migrate | I6: Ready | J6: git-lfs
A7: AI Engineer Track/Advanced Agentic AI Systems Engineering/02_Programme_Guides/ASSESSMENT_PACK.md | C7: bab08e0c7cd32cc4825c36d1055c9aa53766a813ed75cd4ab50ccc2a842cf3d9 | D7: 17776 | E7: SDA-AIE-311 | F7: Assessment | G7: catalog/ai-engineer/SDA-AIE-311-agentic-ai-systems-engineering/assessments/ASSESSMENT_PACK.md | H7: Migrate | I7: Ready | J7: git
A8: AI Engineer Track/Advanced Agentic AI Systems Engineering/02_Programme_Guides/INSTRUCTOR_DELIVERY_GUIDE.md | C8: 8a11598495f6f08dd90759eafcb0bdab2f642bb5195945eac6196e75304630e9 | D8: 27808 | E8: SDA-AIE-311 | F8: Instructor guide (delivery) | G8: catalog/ai-engineer/SDA-AIE-311-agentic-ai-systems-engineering/resources/instructor/INSTRUCTOR_DELIVERY_GUIDE.md | H8: Migrate | I8: Ready | J8: git
A9: AI Engineer Track/Advanced Agentic AI Systems Engineering/02_Programme_Guides/PARTICIPANT_HANDBOOK.md | C9: 4119c3df847bc214fd19dc212de3ae01a23f7de865a1074900935e29c0aa469f | D9: 40515 | E9: SDA-AIE-311 | F9: Participant material | G9: catalog/ai-engineer/SDA-AIE-311-agentic-ai-systems-engineering/resources/participant/PARTICIPANT_HANDBOOK.md | H9: Migrate | I9: Ready | J9: git
A10: AI Engineer Track/Advanced Agentic AI Systems Engineering/02_Programme_Guides/PROGRAMME_OVERVIEW.md | C10: c5ace92269972aeb5a67c0d1fd37288ceca00bee188873bbc53f0f9ddcb1f96b | D10: 9472 | E10: SDA-AIE-311 | F10: Programme guide | G10: catalog/ai-engineer/SDA-AIE-311-agentic-ai-systems-engineering/resources/PROGRAMME_OVERVIEW.md | H10: Migrate | I10: Ready | J10: git
A11: AI Engineer Track/Advanced Agentic AI Systems Engineering/02_Programme_Guides/RESOURCES.md | C11: 3162834b9a74e95887d884e7a921a2a037f104478c83299ea60af1dd6382d7af | D11: 22183 | E11: SDA-AIE-311 | F11: Programme guide | G11: catalog/ai-engineer/SDA-AIE-311-agentic-ai-systems-engineering/resources/RESOURCES.md | H11: Migrate | I11: Ready | J11: git
A12: AI Engineer Track/Advanced Agentic AI Systems Engineering/02_Programme_Guides/SETUP_GUIDE.md | C12: d7317ee296db14eb536b3a5fe2e20b1803e22f87f77f9949136601976c3445d8 | D12: 14191 | E12: SDA-AIE-311 | F12: Programme guide | G12: catalog/ai-engineer/SDA-AIE-311-agentic-ai-systems-engineering/resources/SETUP_GUIDE.md | H12: Migrate | I12: Ready | J12: git
A13: AI Engineer Track/Advanced Agentic AI Systems Engineering/02_Programme_Guides/VISUAL_ASSET_BRIEF.md | C13: 14709e59820229251101ebed710b53f1bac65972ab3b3eaf2f4f9920e6643394 | D13: 25085 | E13: SDA-AIE-311 | F13: Programme guide | G13: catalog/ai-engineer/SDA-AIE-311-agentic-ai-systems-engineering/resources/VISUAL_ASSET_BRIEF.md | H13: Migrate | I13: Ready | J13: git
A14: AI Engineer Track/Advanced Agentic AI Systems Engineering/03_Course_Repository/tawseel-agentic-ai.zip | C14: 2fc08e6b2cffd702c9863bd133c6c110f54319628ca9c50ed9b2f1af26f016d6 | D14: 1161637 | E14: SDA-AIE-311 | F14: Archive | H14: Container | I14: Ready | K14: Members classified individually
A15: AI Engineer Track/Advanced Agentic AI Systems Engineering/03_Course_Repository/tawseel-agentic-ai.zip | B15: tawseel-agentic-ai/.dockerignore | C15: 23c3bda71253c49714e08e4ef28cfe359f173c44b143fc47c5f9719f31842725 | D15: 590 | E15: SDA-AIE-311 | F15: Lab repository | G15: catalog/ai-engineer/SDA-AIE-311-agentic-ai-systems-engineering/labs/tawseel-agentic-ai/.dockerignore | H15: Extract | I15: Ready | J15: git
A16: AI Engineer Track/Advanced Agentic AI Systems Engineering/03_Course_Repository/tawseel-agentic-ai.zip | B16: tawseel-agentic-ai/.env.example | C16: 9ce666efe30536bca9f9b66dd60404292a6eb3b9fe8678864d05772dc893fa14 | D16: 2070 | E16: SDA-AIE-311 | F16: Lab repository | G16: catalog/ai-engineer/SDA-AIE-311-agentic-ai-systems-engineering/labs/tawseel-agentic-ai/.env.example | H16: Extract | I16: Ready | J16: git
A17: AI Engineer Track/Advanced Agentic AI Systems Engineering/03_Course_Repository/tawseel-agentic-ai.zip | B17: tawseel-agentic-ai/.github/workflows/ci.yml | C17: 104be6860c06099cdcc0939b55aa9f835e4600322c88aaaf319bc5a143f870a8 | D17: 7675 | E17: SDA-AIE-311 | F17: Lab repository | G17: catalog/ai-engineer/SDA-AIE-311-agentic-ai-systems-engineering/labs/tawseel-agentic-ai/.github/workflows/ci.yml | H17: Extract | I17: Ready | J17: git
A18: AI Engineer Track/Advanced Agentic AI Systems Engineering/03_Course_Repository/tawseel-agentic-ai.zip | B18: tawseel-agentic-ai/.gitignore | C18: 6d7e9097d691c03851a32f26d0edc7ca6b9b16b50eaa29d0af2e52c8233e5d9e | D18: 1286 | E18: SDA-AIE-311 | F18: Lab repository | G18: catalog/ai-engineer/SDA-AIE-311-agentic-ai-systems-engineering/labs/tawseel-agentic-ai/.gitignore | H18: Extract | I18: Ready | J18: git
A19: AI Engineer Track/Advanced Agentic AI Systems Engineering/03_Course_Repository/tawseel-agentic-ai.zip | B19: tawseel-agentic-ai/CONTRIBUTING.md | C19: 5a7600bb500bf3bc302c8eccbc2d130cf5d774836be5ab1283b44b4041d26c04 | D19: 3728 | E19: SDA-AIE-311 | F19: Lab repository | G19: catalog/ai-engineer/SDA-AIE-311-agentic-ai-systems-engineering/labs/tawseel-agentic-ai/CONTRIBUTING.md | H19: Extract | I19: Ready | J19: git
A20: AI Engineer Track/Advanced Agentic AI Systems Engineering/03_Course_Repository/tawseel-agentic-ai.zip | B20: tawseel-agentic-ai/Dockerfile | C20: 1df13ec119fc3ca476fe83c0634dce31bd29c7b1582efe55f386d420c6282b82 | D20: 1911 | E20: SDA-AIE-311 | F20: Lab repository | G20: catalog/ai-engineer/SDA-AIE-311-agentic-ai-systems-engineering/labs/tawseel-agentic-ai/Dockerfile | H20: Extract | I20: Ready | J20: git
A21: AI Engineer Track/Advanced Agentic AI Systems Engineering/03_Course_Repository/tawseel-agentic-ai.zip | B21: tawseel-agentic-ai/LICENSE | C21: 7e764ea596fddcfc53844d5ac04581d89f75768ea098c6fe798ba6c00e98db83 | D21: 1035 | E21: SDA-AIE-311 | F21: Lab repository | G21: catalog/ai-engineer/SDA-AIE-311-agentic-ai-systems-engineering/labs/tawseel-agentic-ai/LICENSE | H21: Extract | I21: Ready | J21: git
A22: AI Engineer Track/Advanced Agentic AI Systems Engineering/03_Course_Repository/tawseel-agentic-ai.zip | B22: tawseel-agentic-ai/Makefile | C22: e514b8428b3f9185f855be8d082cc68c6e4528fa96a08dad5d888ee3adafef59 | D22: 5375 | E22: SDA-AIE-311 | F22: Lab repository | G22: catalog/ai-engineer/SDA-AIE-311-agentic-ai-systems-engineering/labs/tawseel-agentic-ai/Makefile | H22: Extract | I22: Ready | J22: git
A23: AI Engineer Track/Advanced Agentic AI Systems Engineering/03_Course_Repository/tawseel-agentic-ai.zip | B23: tawseel-agentic-ai/README.md | C23: 7b21e64adf36e2b4412ff0273875aa26d046d173d99d088f34b108ad26a14c25 | D23: 5849 | E23: SDA-AIE-311 | F23: Lab repository | G23: catalog/ai-engineer/SDA-AIE-311-agentic-ai-systems-engineering/labs/tawseel-agentic-ai/README.md | H23: Extract | I23: Ready | J23: git
A24: AI Engineer Track/Advanced Agentic AI Systems Engineering/03_Course_Repository/tawseel-agentic-ai.zip | B24: tawseel-agentic-ai/capstone/README.md | C24: 9eadf3bcba3a2ba25ca1b5f53b74d13e6663e55341c2589208e5757500dbf3b5 | D24: 6235 | E24: SDA-AIE-311 | F24: Lab repository | G24: catalog/ai-engineer/SDA-AIE-311-agentic-ai-systems-engineering/labs/tawseel-agentic-ai/capstone/README.md | H24: Extract | I24: Ready | J24: git
A25: AI Engineer Track/Advanced Agentic AI Systems Engineering/03_Course_Repository/tawseel-agentic-ai.zip | B25: tawseel-agentic-ai/capstone/checklist.md | C25: eb1fd7f48bc92c2f27f3effc1efb6823b0d7aa302a5d1131583beefa2e14a5b1 | D25: 5809 | E25: SDA-AIE-311 | F25: Lab repository | G25: catalog/ai-engineer/SDA-AIE-311-agentic-ai-systems-engineering/labs/tawseel-agentic-ai/capstone/checklist.md | H25: Extract | I25: Ready | J25: git
A26: AI Engineer Track/Advanced Agentic AI Systems Engineering/03_Course_Repository/tawseel-agentic-ai.zip | B26: tawseel-agentic-ai/capstone/grading/instructor_grading_sheet.md | C26: 8d591ee690ed4bec28ee4df03813dfd5b9ae6b61a7e17be6ea96a996a6c6e897 | D26: 3878 | E26: SDA-AIE-311 | F26: Lab repository | G26: catalog/ai-engineer/SDA-AIE-311-agentic-ai-systems-engineering/labs/tawseel-agentic-ai/capstone/grading/instructor_grading_sheet.md | H26: Extract | I26: Ready | J26: git
... A335: AI Engineer Track/Advanced Agentic AI Systems Engineering/03_Course_Repository/tawseel-agentic-ai.zip | B335: tawseel-agentic-ai/tests/unit/test_tools.py | C335: 47b5336351a2d7b09a1c452d403ca19dace372d1975f35bb824b156fc58c8edb | D335: 12438 | E335: SDA-AIE-311 | F335: Lab repository | G335: catalog/ai-engineer/SDA-AIE-311-agentic-ai-systems-engineering/labs/tawseel-agentic-ai/tests/unit/test_tools.py | H335: Extract | I335: Ready | J335: git
A336: AI Engineer Track/Advanced Agentic AI Systems Engineering/INSTRUCTOR_PACKAGE.md | C336: 5ef69eaabb97b570e8c2e7dc7999138d8d7b809554d9cf3b27b8287a8590c1e6 | D336: 223083 | E336: SDA-AIE-311 | F336: Instructor guide | G336: catalog/ai-engineer/SDA-AIE-311-agentic-ai-systems-engineering/instructor-guide.md | H336: Convert | I336: Ready | J336: git | K336: Body preserved verbatim under a governance header
A337: AI Engineer Track/Advanced Agentic AI Systems Engineering/README_START_HERE.md | C337: 60da7b0c7305db264ebd4b86fc563a036afa8652b9e08c81a75f1745bcbc784f | D337: 10546 | E337: SDA-AIE-311 | F337: Programme guide | G337: catalog/ai-engineer/SDA-AIE-311-agentic-ai-systems-engineering/resources/README_START_HERE.md | H337: Migrate | I337: Ready | J337: git
A338: AI Engineer Track/Advanced Agentic AI Systems Engineering/SDA-AIE-311_Program_Package.zip | C338: 8e54a71f16f99be7ac26b0a4e5c549ff74ff722d67a5e0ada5a741dc16f2dd71 | D338: 3049710 | E338: SDA-AIE-311 | F338: Archive | H338: Container | I338: Duplicate | K338: Bundle of the loose files + tawseel repo; only deck_source/ is unique
A339: AI Engineer Track/Advanced Agentic AI Systems Engineering/SDA-AIE-311_Program_Package.zip | B339: SDA-AIE-311_Program_Package/01_Training_Deck/SDA-AIE-311_Agentic_AI_Systems_Engineering_Deck.pdf | C339: 0f677a22fbace5ab416206900145bb94018f1162c17bfe097b3958063b893855 | D339: 2620813 | E339: SDA-AIE-311 | F339: Bundle copy | H339: Duplicate | I339: Duplicate | K339: Same file migrated from the loose folder / tawseel zip
A340: AI Engineer Track/Advanced Agentic AI Systems Engineering/SDA-AIE-311_Program_Package.zip | B340: SDA-AIE-311_Program_Package/01_Training_Deck/SDA-AIE-311_Agentic_AI_Systems_Engineering_Deck.pptx | C340: 7205be374a1ff9475c25efe2a51114323bc10dfd09900c005b3aba97759072f3 | D340: 6972619 | E340: SDA-AIE-311 | F340: Bundle copy | H340: Duplicate | I340: Duplicate | K340: Same file migrated from the loose folder / tawseel zip
A341: AI Engineer Track/Advanced Agentic AI Systems Engineering/SDA-AIE-311_Program_Package.zip | B341: SDA-AIE-311_Program_Package/01_Training_Deck/deck_source/CONTENT_SPEC.md | C341: 80cbc3d00d2b12cc6d94cdca1a2d76f15fb4a12e7e33976d292ce5cb67949a07 | D341: 9361 | E341: SDA-AIE-311 | F341: Slides source | G341: catalog/ai-engineer/SDA-AIE-311-agentic-ai-systems-engineering/slides/deck-source/CONTENT_SPEC.md | H341: Extract | I341: Ready | J341: git | K341: Deck build sources — only unique content of the bundle
A342: AI Engineer Track/Advanced Agentic AI Systems Engineering/SDA-AIE-311_Program_Package.zip | B342: SDA-AIE-311_Program_Package/01_Training_Deck/deck_source/content/00_front.json | C342: 5cb37ba92567da8c6dbb3c17e723e723b02db429a6b775ec34272a461c914938 | D342: 10549 | E342: SDA-AIE-311 | F342: Slides source | G342: catalog/ai-engineer/SDA-AIE-311-agentic-ai-systems-engineering/slides/deck-source/content/00_front.json | H342: Extract | I342: Ready | J342: git | K342: Deck build sources — only unique content of the bundle
A343: AI Engineer Track/Advanced Agentic AI Systems Engineering/SDA-AIE-311_Program_Package.zip | B343: SDA-AIE-311_Program_Package/01_Training_Deck/deck_source/content/10_day1.json | C343: eefdc07fdd71d79b3bffafceb0bc12517cef2c71f44d7cd99ffd7d0454d6bbc8 | D343: 63397 | E343: SDA-AIE-311 | F343: Slides source | G343: catalog/ai-engineer/SDA-AIE-311-agentic-ai-systems-engineering/slides/deck-source/content/10_day1.json | H343: Extract | I343: Ready | J343: git | K343: Deck build sources — only unique content of the bundle
A344: AI Engineer Track/Advanced Agentic AI Systems Engineering/SDA-AIE-311_Program_Package.zip | B344: SDA-AIE-311_Program_Package/01_Training_Deck/deck_source/content/20_day2.json | C344: b9de017df9271f40b619b79a815d6762d0cb6b8a565c540c99a107099b2d0c83 | D344: 61539 | E344: SDA-AIE-311 | F344: Slides source | G344: catalog/ai-engineer/SDA-AIE-311-agentic-ai-systems-engineering/slides/deck-source/content/20_day2.json | H344: Extract | I344: Ready | J344: git | K344: Deck build sources — only unique content of the bundle
A345: AI Engineer Track/Advanced Agentic AI Systems Engineering/SDA-AIE-311_Program_Package.zip | B345: SDA-AIE-311_Program_Package/01_Training_Deck/deck_source/content/30_day3.json | C345: a4d77f3a04f69560552fb3e9af3d020179c28da7d5fd2bb2e274ac90993a6f4a | D345: 75768 | E345: SDA-AIE-311 | F345: Slides source | G345: catalog/ai-engineer/SDA-AIE-311-agentic-ai-systems-engineering/slides/deck-source/content/30_day3.json | H345: Extract | I345: Ready | J345: git | K345: Deck build sources — only unique content of the bundle
A346: AI Engineer Track/Advanced Agentic AI Systems Engineering/SDA-AIE-311_Program_Package.zip | B346: SDA-AIE-311_Program_Package/01_Training_Deck/deck_source/content/40_day4.json | C346: 9bb6c8642f8dd4540238d2f496c659053aa8b49eb69054714039149afd5d6149 | D346: 70534 | E346: SDA-AIE-311 | F346: Slides source | G346: catalog/ai-engineer/SDA-AIE-311-agentic-ai-systems-engineering/slides/deck-source/content/40_day4.json | H346: Extract | I346: Ready | J346: git | K346: Deck build sources — only unique content of the bundle
A347: AI Engineer Track/Advanced Agentic AI Systems Engineering/SDA-AIE-311_Program_Package.zip | B347: SDA-AIE-311_Program_Package/01_Training_Deck/deck_source/content/50_day5.json | C347: a1335ad87a519cb9e299481f23494b0d0cd2c738ab2252e0dec4eabead773219 | D347: 62577 | E347: SDA-AIE-311 | F347: Slides source | G347: catalog/ai-engineer/SDA-AIE-311-agentic-ai-systems-engineering/slides/deck-source/content/50_day5.json | H347: Extract | I347: Ready | J347: git | K347: Deck build sources — only unique content of the bundle
A348: AI Engineer Track/Advanced Agentic AI Systems Engineering/SDA-AIE-311_Program_Package.zip | B348: SDA-AIE-311_Program_Package/01_Training_Deck/deck_source/render.js | C348: 3ca4ba650fd4ba10a7adc51fa38de96a3c2b8ebe039f1c26ff3242e226ca5e92 | D348: 30189 | E348: SDA-AIE-311 | F348: Slides source | G348: catalog/ai-engineer/SDA-AIE-311-agentic-ai-systems-engineering/slides/deck-source/render.js | H348: Extract | I348: Ready | J348: git | K348: Deck build sources — only unique content of the bundle
...
